Workbook
Name Check1_1: #REF!
Name Check2_1: #REF!
Name Check3_1: #REF!
Name Check4_1: #REF!
Name check5: #REF!
Name Check5_1: #REF!
Name Check6_1: #REF!
Name Check7_1: #REF!
Name oijjjojoijpojpoi: #REF!
Name Plat_LastSaved: #REF!
Name Test: #REF!
Name Test4: #REF!

Sheet Overview
D3: Prospect Name/Number: | Q3: 32-11N-25W / Diversified
C5: Section | H5: 32 | L5: Township | R5: 11N | Y5: Range | AC5: 25W
D7: County | H7: Beckham | U7: State | X7: Oklahoma
B9: Containing 640.00 acres, more or less
X15: T1: N/2 NE/4 + SW/4 NE/4 120 ac
R22: T2: SE/4 NE/4 + E/2 SE/4 120 ac
E26: T4: SW/4 160 ac | M26: T3: NW/4 160 ac
X34: T5: W/2 SE/4 80 ac
B44: ATTACHMENTS: | I44: OWNERSHIP REPORT DATED: | Y44: LAST ENTRY:
I46: TITLE OPINION UPDATE DATED: | Y46: LAST ENTRY:
G48: x | I48: CURSORY REPORT DATED: | S48: 46218.208 | Y48: LAST ENTRY: | AC48: 2485/685
I50: COUNTY CERTIFICATION DATE:
B52: REMARKS: | F52: HOLD_NO_RELEASE — source-limited cursory update through 2026-07-15. Diversified Production LLC is supported only through the OK48147.001.1 identity path (2395/415–464; 2400/551–567); exact WI, NRI, ORRI and net acres remain NOT DETERMINED. 1697/236 is an assignment, not a proved base OGL. Carlson 32-11-25 7H carve (2183/174; 2185/639) remains unmapped to OK48147.001.1. Current tract display is gross reporting control only; mineral-title tract control remains OPEN. Local OCC RBDMS snapshot 2026-07-09 lists 11 Section 32 records. Historical OCC Cause CD 59995 / Order 156126 was reviewed, but current order effect, other orders, production continuity and lease-by-lease HBP remain NEEDS VERIFICATION.
B56: EXAMINER: | F56: NHE

Sheet Title 
B4: TRACT 1: | C4: N/2 NE/4 and SW/4 NE/4
B5: Containing: | C5: 120.00 acres, more or less
B7: Mineral Owner | C7: Net Acres | D7: OGL No. | E7: Royalty | F7: Expiration | G7: Comments
B8: Hanks, Darrell Lee, et al. | G8: SURFACE OWNER ONLY — MINERAL OWNERSHIP OPEN. Addr: 3704 S.E. 34th Ave., Amarillo, TX 79103. Assessor Acct. 050005625; Bk. 2290/P.494 (surface/current-owner lead only)
B9: Mineral / leasehold chain | G9: Historical Crook/Randel lease refs (264/345; 352/719; 352/721) — lessor chain OPEN. Diversified OK48147.001.1 path may burden leasehold but tract-level WI/NRI/net acres OPEN (2395/462; 2400/566).
B27: REPORT TOTAL | C27: =SUM(C8:C25) | G27: OPEN / SOURCE-LIMITED — REPORT TOTAL formula preserved; blank owner NMA ≠ zero proof.
B28: TOTAL | C28: =SUM(C8:C25)
B31: TRACT 2: | C31: SE/4 NE/4 and E/2 SE/4
B32: Containing: | C32: 120.00 acres, more or less
B34: Mineral Owner | C34: Net Acres | D34: OGL No. | E34: Royalty | F34: Expiration | G34: Comments
B35: Crook, Ola Mae | G35: SURFACE OWNER ONLY — MINERAL OWNERSHIP OPEN. Addr: 11277 N 1750 Rd., Sayre, OK 73662-4033. Assessor Accts. 050005631 / 050005630; Bk. 2111/P.585 (surface/current-owner lead only)
B36: Acciona Wind Energy USA LLC | G36: SURFACE OWNER ONLY — MINERAL OWNERSHIP OPEN. Addr: 55 E. Monroe St., Suite 1925, Chicago, IL 60603. Assessor Acct. 050020323; Bk. 2052/P.466 — SURFACE/WIND ONLY; no mineral interest attributed
B37: Mineral / leasehold chain | G37: Pearl wellbore/depth branch historical (845/47; 872/279) — not present WI. Diversified OK48147.001.1 path may burden leasehold but tract-level WI/NRI/net acres OPEN (2395/462; 2400/566).
B50: REPORT TOTAL | C50: =SUM(C35:C49) | G50: OPEN / SOURCE-LIMITED — REPORT TOTAL formula preserved; blank owner NMA ≠ zero proof.
B51: TOTAL | C51: =SUM(C35:C49)
B54: TRACT 3: | C54: NW/4
B55: Containing: | C55: 160.00 acres, more or less
B57: Mineral Owner | C57: Net Acres | D57: OGL No. | E57: Royalty | F57: Expiration | G57: Comments
B58: Maddoux, Gerry L., Living Trust | G58: SURFACE OWNER ONLY — MINERAL OWNERSHIP OPEN. Addr: 9055 N Morning Glory Rd., Paradise Valley, AZ 85253. Assessor Acct. 050005626 (surface/current-owner lead only)
B59: Sumpter, Elizabeth | G59: SURFACE OWNER ONLY — MINERAL OWNERSHIP OPEN. Addr: 11224 N 1740 Rd., Sweetwater, OK 73666. Assessor Acct. 050005628; Bk. 2302/P.166 (surface/current-owner lead only)
B60: Johnson, Abby Colleen | G60: SURFACE OWNER ONLY — MINERAL OWNERSHIP OPEN. Addr: 708 N State Ave., Apt. 5, Weatherford, OK 73096. Assessor Acct. 050024355; Bk. 2483/P.572 (surface/current-owner lead only)
B61: Mineral / leasehold chain | G61: Historical N/2 below-top-Hunton branch OPEN (502/265; 839/188; 1014/75). Diversified OK48147.001.1 path may burden leasehold but tract-level WI/NRI/net acres OPEN (2395/462; 2400/566).
B72: REPORT TOTAL | C72: =SUM(C58:C71) | G72: OPEN / SOURCE-LIMITED — REPORT TOTAL formula preserved; blank owner NMA ≠ zero proof.
B73: TOTAL | C73: =SUM(C58:C71)
B75: TRACT 4: | C75: SW/4
B76: Containing: | C76: 160.00 acres, more or less
B79: Mineral Owner | C79: Net Acres | D79: OGL No. | E79: Royalty | F79: Expiration | G79: Comments
B80: Maddoux, Gerry L., Living Trust | G80: SURFACE OWNER ONLY — MINERAL OWNERSHIP OPEN. Addr: 9055 N Morning Glory Rd., Paradise Valley, AZ 85253. Assessor Acct. 050005627 (surface/current-owner lead only)
B81: Maddoux, Gail, Trustee of Revocable Trust | G81: SURFACE OWNER ONLY — MINERAL OWNERSHIP OPEN. Addr: P.O. Box 111078, Naples, FL 34108-0000. Assessor Acct. 050005632; Bk. 1868/P.526 (surface/current-owner lead only)
B82: Sumpter, Elizabeth | G82: SURFACE OWNER ONLY — MINERAL OWNERSHIP OPEN. Addr: 11224 N 1740 Rd., Sweetwater, OK 73666. Assessor Acct. 050005629; Bk. 2391/P.68 (surface/current-owner lead only)
B83: Mineral / leasehold chain | G83: Overlapping historical OGL refs (307/31; 340/302 et seq.) — not additive NMA. Diversified OK48147.001.1 path may burden leasehold but tract-level WI/NRI/net acres OPEN (2395/462; 2400/566).
B89: REPORT TOTAL | C89: =SUM(C81:C88) | G89: OPEN / SOURCE-LIMITED — REPORT TOTAL formula preserved; blank owner NMA ≠ zero proof.
B90: TOTAL | C90: =SUM(C81:C88)
B92: TRACT 5: | C92: W/2 SE/4
B93: Containing: | C93: 80.00 acres, more or less
B96: Mineral Owner | C96: Net Acres | D96: OGL No. | E96: Royalty | F96: Expiration | G96: Comments
B97: Sumpter, Elizabeth | G97: SURFACE OWNER ONLY — MINERAL OWNERSHIP OPEN. Addr: 11224 N 1740 Rd., Sweetwater, OK 73666. Assessor parcel within Acct. 050005629; Bk. 2391/P.68 (surface/current-owner lead only)
B98: Mineral / leasehold chain | G98: Historical LeGrand/Union/Leede refs (307/31; 872/279) — base OGL terms OPEN. Diversified OK48147.001.1 path may burden leasehold but tract-level WI/NRI/net acres OPEN (2395/462; 2400/566).
B112: REPORT TOTAL | C112: =SUM(C97:C111) | G112: OPEN / SOURCE-LIMITED — REPORT TOTAL formula preserved; blank owner NMA ≠ zero proof.
B113: TOTAL | C113: =SUM(C97:C111)
...

Sheet OGL
A1: OGL # | B1: LH | C1: Image # | D1: Instrument | E1: Bk./Pg. | F1: Execution Date | G1: Filing Date | H1: Grantor | I1: Grantee | J1: Legal Description | K1: Misc. Notes | L1: Term | M1: Gross Acres | N1: Tracts | O1: Exp Date | P1: Net Mineral Acres | Q1: Royalty | V1: Depth Clause | W1: Option to Extend | X1: No Warranty Clause | Y1: Top Lease Clause
A2: 1 | B2: 872/279 — lease exhibit reference | C2: L-007 imgs 4388–4393; L-001 imgs 1940–1943 where applicable | D2: LEASE REFERENCE ONLY | E2: 63/33 | F2: 17484 | H2: Garretts | I2: C.E. McKinley | J2: E/2 SE/4 | K2: Original lease not reviewed. Lease date/legal are exhibit references, not a lease-specific page isolation. Recording date, term, royalty, clauses, expiration, NMA and HBP remain open. Nominal acreage is an express aliquot assumption. | M2: 80 | N2: 2 | V2: Later assignment treatment only: Below 11,100 ft in later assignment exhibit; original lease depth clause OPEN
A3: 2 | B3: 872/279 — lease exhibit reference | C3: L-007 imgs 4388–4393; L-001 imgs 1940–1943 where applicable | D3: LEASE REFERENCE ONLY | E3: 264/345 | F3: 26334 | H3: Charlie B. and Ina Pearl Crook | I3: Union | J3: NE/4 | K3: Original lease not reviewed. Lease date/legal are exhibit references, not a lease-specific page isolation. Recording date, term, royalty, clauses, expiration, NMA and HBP remain open. Nominal acreage is an express aliquot assumption. | M3: 160 | N3: 1–2 | V3: Later assignment treatment only: Later deep assignment subject; original lease depth clause OPEN
A4: 3 | B4: 872/279 — lease exhibit reference | C4: L-007 imgs 4388–4393; L-001 imgs 1940–1943 where applicable | D4: LEASE REFERENCE ONLY | E4: 307/31 | F4: 27879 | H4: Cora B. LeGrand | I4: Union | J4: W/2 SE/4 and S/2 SW/4 | K4: Original lease not reviewed. Lease date/legal are exhibit references, not a lease-specific page isolation. Recording date, term, royalty, clauses, expiration, NMA and HBP remain open. Nominal acreage is an express aliquot assumption. | M4: 160 | N4: 4–5 | V4: Later assignment treatment only: Later deep assignment subject; original lease depth clause OPEN
A5: 4 | B5: 872/279 — lease exhibit reference | C5: L-007 imgs 4388–4393; L-001 imgs 1940–1943 where applicable | D5: LEASE REFERENCE ONLY | E5: 340/302 | F5: 28412 | H5: Gertrude L. LaFortune et al. | I5: Union | J5: N/2 SW/4 | K5: Original lease not reviewed. Lease date/legal are exhibit references, not a lease-specific page isolation. Recording date, term, royalty, clauses, expiration, NMA and HBP remain open. Nominal acreage is an express aliquot assumption. | M5: 80 | N5: 4 | V5: Later assignment treatment only: Later deep assignment subject; original lease depth clause OPEN
A6: 5 | B6: 872/279 — lease exhibit reference | C6: L-007 imgs 4388–4393; L-001 imgs 1940–1943 where applicable | D6: LEASE REFERENCE ONLY | E6: 340/304 | F6: 28412 | H6: Gertrude LaFortune, widow | I6: Union | J6: N/2 SW/4 | K6: Original lease not reviewed. Lease date/legal are exhibit references, not a lease-specific page isolation. Recording date, term, royalty, clauses, expiration, NMA and HBP remain open. Nominal acreage is an express aliquot assumption. | M6: 80 | N6: 4 | V6: Later assignment treatment only: Overlap/chain relationship must be read; original lease depth clause OPEN
A7: 6 | B7: 872/279 — lease exhibit reference | C7: L-007 imgs 4388–4393; L-001 imgs 1940–1943 where applicable | D7: LEASE REFERENCE ONLY | E7: 340/323 | F7: 28397 | H7: George T. Harrison Jr. and Renata Harrison | I7: Union | J7: N/2 NW/4 and N/2 SW/4 | K7: Original lease not reviewed. Lease date/legal are exhibit references, not a lease-specific page isolation. Recording date, term, royalty, clauses, expiration, NMA and HBP remain open. Nominal acreage is an express aliquot assumption. | M7: 160 | N7: 3–4 | V7: Later assignment treatment only: Later deep assignment subject; original lease depth clause OPEN
A8: 7 | B8: 872/279 — lease exhibit reference | C8: L-007 imgs 4388–4393; L-001 imgs 1940–1943 where applicable | D8: LEASE REFERENCE ONLY | E8: 342/564 | F8: 28397 | H8: Carol Seidenbach Leach | I8: Union | J8: N/2 SW/4 | K8: Original lease not reviewed. Lease date/legal are exhibit references, not a lease-specific page isolation. Recording date, term, royalty, clauses, expiration, NMA and HBP remain open. Nominal acreage is an express aliquot assumption. | M8: 80 | N8: 4 | V8: Later assignment treatment only: Later deep assignment subject; original lease depth clause OPEN
A9: 8 | B9: 872/279 — lease exhibit reference | C9: L-007 imgs 4388–4393; L-001 imgs 1940–1943 where applicable | D9: LEASE REFERENCE ONLY | E9: 342/566 | F9: 28430 | H9: Cynthia Seidenbach Kruse | I9: Union | J9: N/2 SW/4 | K9: Original lease not reviewed. Lease date/legal are exhibit references, not a lease-specific page isolation. Recording date, term, royalty, clauses, expiration, NMA and HBP remain open. Nominal acreage is an express aliquot assumption. | M9: 80 | N9: 4 | V9: Later assignment treatment only: Later deep assignment subject; original lease depth clause OPEN
A10: 9 | B10: 872/279 — lease exhibit reference | C10: L-007 imgs 4388–4393; L-001 imgs 1940–1943 where applicable | D10: LEASE REFERENCE ONLY | E10: 352/719 | F10: 28626 | H10: F.L. Randel | I10: Union | J10: NE/4 | K10: Original lease not reviewed. Lease date/legal are exhibit references, not a lease-specific page isolation. Recording date, term, royalty, clauses, expiration, NMA and HBP remain open. Nominal acreage is an express aliquot assumption. | M10: 160 | N10: 1–2 | V10: Later assignment treatment only: Later deep assignment subject; original lease depth clause OPEN
A11: 10 | B11: 872/279 — lease exhibit reference | C11: L-007 imgs 4388–4393; L-001 imgs 1940–1943 where applicable | D11: LEASE REFERENCE ONLY | E11: 352/721 | F11: 28626 | H11: J.L. Randel | I11: Union | J11: NE/4 | K11: Original lease not reviewed. Lease date/legal are exhibit references, not a lease-specific page isolation. Recording date, term, royalty, clauses, expiration, NMA and HBP remain open. Nominal acreage is an express aliquot assumption. | M11: 160 | N11: 1–2 | V11: Later assignment treatment only: Later deep assignment subject; original lease depth clause OPEN
A12: 11 | B12: 872/279 — lease exhibit reference | C12: L-007 imgs 4388–4393; L-001 imgs 1940–1943 where applicable | D12: LEASE REFERENCE ONLY | E12: 376/369 | F12: 28935 | H12: Great Western Oil & Gas | I12: Union | J12: NE/4 | K12: Original lease not reviewed. Lease date/legal are exhibit references, not a lease-specific page isolation. Recording date, term, royalty, clauses, expiration, NMA and HBP remain open. Nominal acreage is an express aliquot assumption. | M12: 160 | N12: 1–2 | V12: Later assignment treatment only: Later deep assignment subject; original lease depth clause OPEN
A13: OPEN | B13: OK48147.001.1 schedule cites 1697/236 — Assignment I-2001-004316 (Staghorn→CHK), NOT a base OGL. True base oil & gas lease for this modern lease ID remains OPEN.
A14: OPEN | B14: Carlson 32-11-25 7H wellbore carve: I-2015-000819 / I-2015-001373 (2185/639). Intersection with OK48147/Garrett leasehold unmapped; do not compute full-leasehold WI.
A15: OPEN | B15: CHK → Tapstone Energy → DP Legacy Tapstone facial bridge for OK48147.001.1 is not page-proven from available images (index/long-description cluster only).

Sheet PLAT
B22: SECTION 32-11N-25W TRACT CONTROL (GROSS ALIQUOTS; NOT OWNERSHIP)
B23: Tract 1 | C23: N/2 NE/4 + SW/4 NE/4 | G23: 120 ac
B24: Tract 2 | C24: SE/4 NE/4 + E/2 SE/4 | G24: 120 ac
B25: Tract 3 | C25: NW/4 | G25: 160 ac
B26: Tract 4 | C26: SW/4 | G26: 160 ac
B27: Tract 5 | C27: W/2 SE/4 | G27: 80 ac
B28: Total gross acres = 640
B29: Plat source: _PROJECT_FILES\01_SOURCE_READ_ONLY\PLAT_AND_TAX\Section_32_T11N_R25W_Original_GLO_Plat_Crop.png
B30: NOTE: Surface assessor names are NOT proved mineral ownership. Generic template Sec. 18 placeholder map removed.
B31: TRACT CONTROL CONFLICT — displayed aliquots are gross reporting control only and are not proved mineral-title tract control. A conflicting Template/tract-chain system remains documented and OPEN; examiner verification is required. Source: _PROJECT_FILES\03_QA_AND_SUPPORT\FINAL_COMPLETION_PACKAGE\TRACT_CONTROL_DECISION.md

Sheet Runsheet
B1: OGL | C1: Doc Type | D1: Bk/Pg. | E1: Effective Date | F1: Recorded Date | G1: Grantor | H1: Grantee | I1: Legal Description | J1: Notes
A2: 81 | C2: Confirmation of Division / Confirmatory Conveyance | D2: 2395/415–464 | F2: 44883 | G2: DP Legacy Tapstone LLC | H2: Diversified ABS VI Upstream LLC; DP Sooner HoldCo LLC | I2: All 16 Q-Q ticks; long description | J2: I-2022-004838 Confirmation of Division (ER-01 IMAGE). OK48147.001.1 on Exhibit E at 2395/462; interest columns blank. ABS VI — no Sec 32 well on 2395/450. Financing termination 2395/967 is separate.
A3: 86 | C3: Confirmation of Merger / Confirmatory Conveyance | D3: 2400/551–567 | F3: 44987 | G3: DP Sooner HoldCo LLC | H3: Diversified Production LLC | I3: Long description | J3: I-2023-000796 Confirmation of Merger (IMAGE). DP Sooner → Diversified Production LLC; Schedule B includes OK48147.001.1 at 2400/566; legal/interest blank. Quantum NOT YET CALCULABLE.
A4: 53 | C4: Wellbore Sale | D4: 2183/174 | F4: 42053 | G4: Chesapeake affiliates | H4: Linn Operating | I4: Section 32 index marks / extent varies | J4: CHK→Linn wellbore assignment/correction — Carlson 32-11-25 7H (API 35-009-2192300) carve; intersection with OK48147 OPEN.
A5: 54 | C5: Conveyance | D5: 2185/639 | F5: 42094 | G5: Chesapeake affiliates | H5: FourPoint Energy | I5: Section 32 index marks / extent varies | J5: CHK→Linn wellbore assignment/correction — Carlson 32-11-25 7H (API 35-009-2192300) carve; intersection with OK48147 OPEN.
A6: 65 | C6: Assignment | D6: 2371/495–513 | F6: 44573 | G6: Tapstone Energy; Tapstone Midstream | H6: OCM Denali Holdings LLC | I6: Section 32 | J6: Separate parallel instrument; schedule/estate open. | PUBLIC METADATA + INDEX | PHASE8: Tapstone→OCM Denali schedule lists OK48147.001.1 Sec32 (quantum OPEN).
A7: 75 | C7: Merger | D7: 2389/500–580 | F7: 44797 | G7: Diversified Production; DP Legacy Central; merger entities | H7: DP Legacy Tapstone LLC | I7: All Section 32 ticks | J7: Merger plan/certificate and title effect absent. | PUBLIC METADATA + INDEX
A8: 77 | C8: Amended Mortgage | D8: 2389/590–629 | F8: 44797 | G8: Diversified Production; DP Legacy Tapstone | H8: KeyBank | I8: Collateral schedule | J8: Direct Diversified encumbrance; references prior lien. | PUBLIC METADATA + INDEX — BURDEN | Financing/security — not WI vesting.
A9: 96 | C9: Wellbore Assignment | D9: 2434/751–760 | F9: 45526 | G9: Diversified Production; DP Legacy Central | H9: Teocalli Exploration | I9: Countywide long description | J9: Not indexed to subject section in supplied index; pull schedule before excluding. | COUNTYWIDE SCREEN
A10: 50 | C10: Assignment | D10: 1697/574 | F10: 37056 | G10: Staghorn Resources | H10: Chesapeake Exploration | I10: Section 32 index marks / extent varies | J10: Local Section 32 index reconciled; complete copy and schedules absent. Do not infer estate, quantum or operative effect. | INDEX ONLY S-002
A11: 58 | C11: Assignment | D11: 2340/403–433 | F11: 44179 | G11: Chesapeake affiliates | H11: Tapstone Energy LLC | I11: Section 32 index marks / extent varies | J11: Complete copy and schedules absent; county metadata proves only the facial record. Legal, estate, quantum and operative effect remain open. | PUBLIC METADATA + INDEX
A12: 64 | C12: Assignment | D12: 2371/470–494 | F12: 44573 | G12: KL CHK SPV LLC (local handwriting may read K3 CHK) | H12: Diversified Production LLC; OCM Denali Holdings LLC | I12: All 16 Q-Q ticks; long description | J12: County metadata supports KL CHK; local handwriting variant is preserved. Prior working materials reported 12/02/2021 as an instrument date, but it is not independently reconciled; fractions and schedules absent. | PUBLIC METADATA C-001 + INDEX
A13: 80 | C13: Release of Mortgage | D13: 2395/370–414 | F13: 44883 | G13: KeyBank | H13: DP Legacy Tapstone | I13: Collateral schedule | J13: Match collateral and released lien. | PUBLIC METADATA + INDEX | Financing/security — not WI vesting.
A14: 108 | C14: Assignment of OGL | D14: 244/432 | E14: 1969-11-25 exec / 1969-12-01 eff | F14: 1970-01 (day partially legible) | G14: Humble Oil & Refining Company | H14: Union Oil Company of California | I14: E/2 SE/4 Section 32-11N-25W | J14: DIRECT IMAGE 1062 (visually verified 2026-07-13). Assigns O&G lease L-91511 dated 1947-11-13, Cora B. Garrett & S.A. Garrett lessors, rec Bk 63/33. Confidence HIGH (parties/legal/books); MED recording day. Source: Images/1062.jpg
A15: 119 | C15: Assignment recital + Unit interest exhibit | D15: 792/096; also 809/241 | E15: OCC Order 156126 dated 1979-08-06 | F15: OPEN (books 792 & 809) | G15: OPEN — assignor on missing first page | H15: OPEN — assignee on missing first page | I15: Section 32-11N-25W (leases incl. Garrett Bk 63/33; INSOFAR AS cover Sec 32) | J15: [chron 1979-08-06] DIRECT IMAGE 3706 & 3952 (pixels verified, same recital in two recordings). References OCC Order 156126 / Cause CD 59995; Letter/Operating Agmt 1979-11-20 Leede/ENI; Farmout 1979-07-09 Union Oil/Leede. STATED Unit Operating Interest .0495703 (before payout)/.0371778 (after); Unit Net Revenue Interest .0371778/.0278833 — interest of the ASSIGNOR in that instrument, NOT attributed to any current owner. First page (parties/granting clause) NOT in local set. Confidence HIGH (text); assignor/assignee OPEN. Source: Images/3706.jpg, Images/3952.jpg
A16: 68 | C16: Mortgage | D16: 2371/554–588 | F16: 44573 | G16: Tapstone; Diversified Production | H16: KeyBank | I16: Collateral schedule | J16: Direct Diversified lien; applicability and release chain open. | PUBLIC METADATA + INDEX — BURDEN | Financing/security — not WI vesting.
A17: 69 | C17: Financing Statement | D17: 2371/589–625 | F17: 44573 | G17: Tapstone; Diversified Production | H17: KeyBank | I17: Collateral schedule | J17: Direct Diversified UCC/fixture filing; termination chain open. | PUBLIC METADATA + INDEX — BURDEN | Financing/security — not WI vesting.
A18: 78 | C18: Financing Statement | D18: 2389/630–671 | F18: 44797 | G18: DP Legacy Tapstone | H18: KeyBank | I18: Collateral schedule | J18: Collateral and termination must be matched. | PUBLIC METADATA + INDEX — BURDEN | Financing/security — not WI vesting.
A19: 82 | C19: Financing Statement Termination (NOT title conveyance) | D19: 2395/967–972 | F19: 44893 | G19: KeyBank National Association | H19: Tapstone Energy LLC; Diversified Production LLC | I19: Long description | J19: Financing-statement termination only (2395/967–972) — NOT a title conveyance. | PUBLIC METADATA + INDEX
A20: 83 | C20: Termination | D20: 2395/973–978 | F20: 44893 | G20: KeyBank | H20: DP Legacy Tapstone | I20: Financing/UCC | J20: Separate termination; do not treat 2395/967 as releasing it. | PUBLIC METADATA + INDEX
A21: 106 | C21: Affidavit | D21: 2480/824–883 | F21: 46091 | G21: DP Legacy Central; Diversified Production | H21: Public | I21: Countywide long description | J21: Sixty-page affidavit; subject applicability/effect open. | COUNTYWIDE SCREEN
A22: 128 | C22: Producing mineral-interest schedule | D22: 774/227 | E22: OPEN (schedule) | F22: OPEN (book 774) | G22: OPEN (schedule of an estate/owner) | H22: OPEN | I22: E/2 SE/4 (Cora Garrett lease) & N/2 NW/4 (Crook #1-32) Section 32-11N-25W | J22: [chron 1984-01-01] DIRECT IMAGE 3301 (pixels). Item 68: 5/640 int E/2 SE/4, Lease CORA GARRETT, Purchaser Union #19400, NRI .00175780. Item 70: 18/640 int N/2 NW/4, Lease CROOK #1-32, Purchaser Mesa #012600 (gas), NRI .00109870. Fractional owner NRI (NOT Diversified). Confidence HIGH. Source: Images/3301.jpg
A23: 100 | C23: Wellbore Assignment | D23: 2464/200–217 | F23: 45909 | G23: Stephens / Continental Properties affiliates | H23: Diversified Production LLC (metadata string) | I23: Countywide long description | J23: Potential acquisition; metadata parties ambiguous; schedule required. | COUNTYWIDE SCREEN
A24: 329 | C24: Wellbore Assignment | D24: 2151/865-869 | F24: 41698 | G24: BP AMERICA PRODUCTION COMPANY | H24: LINN ENERGY HOLDINGS LLC | I24: S32 T11N R25W | J24: OKCOUNTY API METADATA ONLY — indexed occurrence affecting Section 32. Document images and operative schedules were not purchased or reviewed; do not calculate title quantum from metadata alone.
A25: 14 | C25: Assignment/Reservation | D25: 987/159 | E25: 32113 | F25: 32115 | G25: TCW/Grantham/Carlson | H25: Leede Exploration | I25: McCall/Pearl/Crook table | J25: Historical Leede NRI/ORRI snapshot; corrected ending image. | DIRECT IMAGE L-009; imgs 4840–4852
A26: 51 | C26: Assignment | D26: 1783/118 | F26: 37830 | G26: Mobil Exploration Co. | H26: Chesapeake Exploration | I26: Section 32 index marks / extent varies | J26: Local Section 32 index reconciled; complete copy and schedules absent. Do not infer estate, quantum or operative effect. | INDEX ONLY S-002
A27: 52 | C27: Assignment | D27: 1784/959 | F27: 37851 | G27: Exxon Mobil Corp. | H27: Chesapeake Exploration | I27: Section 32 index marks / extent varies | J27: Local Section 32 index reconciled; complete copy and schedules absent. Do not infer estate, quantum or operative effect. | INDEX ONLY S-002
A28: 55 | C28: Assignment | D28: 2225/1 | F28: 42528 | G28: Chesapeake affiliates | H28: FourPoint Energy | I28: Section 32 index marks / extent varies | J28: Local Section 32 index reconciled; complete copy and schedules absent. Do not infer estate, quantum or operative effect. | INDEX ONLY S-002
A29: 59 | C29: Assignment | D29: 2340/490–519 | F29: 44179 | G29: Chesapeake affiliates | H29: KL CHK SPV LLC (local handwriting may read K3 CHK) | I29: Section 32 index marks / extent varies | J29: Complete copy and schedules absent; county metadata proves only the facial record. Legal, estate, quantum and operative effect remain open. | PUBLIC METADATA + INDEX
A30: 63 | C30: Release of Mortgage | D30: 2371/439–469 | F30: 44573 | G30: Bank of America | H30: Tapstone Energy LLC | I30: Blanket collateral | J30: Match released collateral to 2341/127–153. | PUBLIC METADATA + INDEX | Financing/security — not WI vesting.
A31: 79 | C31: Assignment | D31: 2393/1–698 | F31: 44851 | G31: ConocoPhillips; Louisiana Land & Exploration; Burlington Resources | H31: DP Legacy Central LLC | I31: 698-page schedule / Section 32 index entry | J31: Separate indexed acquisition branch; schedule must be searched for the subject. | PUBLIC METADATA + INDEX
A32: 97 | C32: Merger | D32: 2451/4–23 | F32: 45790 | G32: Diversified Energy Company PLC | H32: Public | I32: Long description / broad index ticks | J32: Merged/surviving entities and title effect absent. | PUBLIC METADATA C-005 + INDEX
A33: 107 | C33: Merger | D33: 2480/903–909 | F33: 46092 | G33: DP/Diversified/Canvas affiliates | H33: Public | I33: No indexed legal description | J33: Corporate effect may be global; plan/certificate required. | COUNTYWIDE SCREEN
A34: 120 | C34: Release and Agreement | D34: 395/618 | E34: 29180 | F34: 1979-12 (Beckham) | G34: Charlie B. Crook & Ima Pearl Crook | H34: Leede Exploration (released) | I34: NE/4 Section 32-11N-25W (Crook lease Bk 264/345) | J34: [chron 1979-11-21] DIRECT IMAGE 1575 (pixels verified). Crooks own surface + portion of minerals under NE/4 Sec 32. O&G lease 1972-02-05 rec Bk 264/345, Lessee Union Oil, covering SW/4 NW/4 & NW/4 SW/4 Sec 28 and NE/4 Sec 32; held by production from Number 1 Bruner Unit. Confidence HIGH. Source: Images/1575.jpg
A35: 141 | C35: Mineral Deed | D35: 1063/164-165 | E35: 32539 | F35: 32540 | G35: GARRETT, GERTRUDE | H35: FOWLER, JOHN; FOWLER, RUTH; GODWIN, JUANITA; KUYKENDALL, MILLARD E; ROBERTS, PAULINE; ROBERTS, ROYICE; STEWART, CARLENE | I35: S32 T11N R25W | J35: OKCOUNTY API METADATA ONLY — indexed occurrence affecting Section 32. Document images and operative schedules were not purchased or reviewed; do not calculate title quantum from metadata alone.
A36: 142 | C36: Mineral Deed | D36: 1063/166-167 | E36: 32520 | F36: 32540 | G36: GARRETT, CARL W | H36: STEWART, CARLENE | I36: S32 T11N R25W | J36: OKCOUNTY API METADATA ONLY — indexed occurrence affecting Section 32. Document images and operative schedules were not purchased or reviewed; do not calculate title quantum from metadata alone.
A37: 174 | C37: Mineral Deed | D37: 1283/4-5 | E37: 33903 | F37: 33904 | G37: GARRETT, CARL | H37: STEWART, CARLENE | I37: S32 T11N R25W | J37: OKCOUNTY API METADATA ONLY — indexed occurrence affecting Section 32. Document images and operative schedules were not purchased or reviewed; do not calculate title quantum from metadata alone.
A38: 256 | C38: Assignment Of Overriding Royalty Interest | D38: 1693/95-96 | E38: 36983 | F38: 37026 | G38: STAGHORN RESOURCES LLC | I38: 32-11N-25W | J38: OKCOUNTY API METADATA ONLY — indexed occurrence affecting Section 32. Document images and operative schedules were not purchased or reviewed; do not calculate title quantum from metadata alone.
A39: 327 | C39: Partial Release Of Mortgage | D39: 2146/23-39 | E39: 41628 | F39: 41646 | G39: UNION BANK N A | H39: CARMEN ACQUISITION LLC; CHESAPEAKE CLEMENTS ACQUISITION LLC; CHESAPEAKE EXPLORATION LIMITED PARTNERSHIP; CHESAPEAKE EXPLORATION LLC; CHESAPEAKE LOUISIANA L P; CHESAPEAKE ROYALTY LLC; EMPRESS LOUISIANA PROPERTIES L P; GOTHIC PRODUCTION LLC; MC LOUISIANA MINERALS LLC; MC MINERAL COMPANY LLC | I39: S32 T11N R25W | J39: OKCOUNTY API METADATA ONLY — indexed occurrence affecting Section 32. Document images and operative schedules were not purchased or reviewed; do not calculate title quantum from metadata alone. | Financing/security — not WI vesting.
A40: 56 | C40: Memorandum | D40: 2225/710 | F40: 42528 | G40: Chesapeake affiliates | H40: FourPoint Energy | I40: Section 32 index marks / extent varies | J40: Local Section 32 index reconciled; complete copy and schedules absent. Do not infer estate, quantum or operative effect. | INDEX ONLY S-002
...

Sheet Index runsheet
B1: OGL | C1: Doc Type | D1: Bk/Pg. | E1: Effective Date | F1: Recorded Date | G1: Grantor | H1: Grantee | I1: Legal Description | J1: Notes

Sheet Tract 1
A1: TRACT 1 — N/2 NE/4 AND SW/4 NE/4 — 120.00 ACRES — FEE MINERAL CHAIN OPEN | E1: Instrument
A2: 1 | B2: TRACT | D2: N/2 NE/4 and SW/4 NE/4, containing 120.00 acres | E2: Image Number
B3: DESCRIPTION | E3: Book / Page
E4: Date
B5: TRACT ACRES | D5: 120 | E5: Conveyance
B6: BASE OGL | D6: Tract 1 | E6: =SUBTOTAL(9,E9:E205) | F6: SURFACE | I6: =IF(I7=0,"","RECHECK") | M6: =IF(M7=0,"","RECHECK") | N6: =IF(N7=0,"","RECHECK") | O6: =IF(O7=0,"","RECHECK") | P6: =IF(P7=0,"","RECHECK") | Q6: =IF(Q7=0,"","RECHECK") | R6: =IF(R7=0,"","RECHECK") | T6: =IF(T7=0,"","RECHECK") | U6: =IF(U7=0,"","RECHECK") | V6: =IF(V7=0,"","RECHECK") | W6: =IF(W7=0,"","RECHECK") | X6: =IF(X7=0,"","RECHECK") | Y6: =IF(Y7=0,"","RECHECK") | Z6: =IF(Z7=0,"","RECHECK") | AA6: =IF(AA7=0,"","RECHECK") | ... AN6: =IF(AN7=0,"","RECHECK") | AR6: =IF(AR7=0,"","RECHECK") | AS6: =IF(AS7=0,"","RECHECK") | AT6: =IF(AT7=0,"","RECHECK") | AU6: =IF(AU7=0,"","RECHECK") | AX6: =IF(AX7=0,"","RECHECK") | AY6: =IF(AY7=0,"","RECHECK") | AZ6: =IF(AZ7=0,"","RECHECK") | BA6: =IF(BA7=0,"","RECHECK") | BB6: =IF(BB7=0,"","RECHECK") | BC6: =IF(BC7=0,"","RECHECK") | BD6: =IF(BD7=0,"","RECHECK") | BE6: =IF(BE7=0,"","RECHECK") | ... GF6: =IF(GF7=0,"","RECHECK")
G7: =SUBTOTAL(9,G10:G206) | H7: =SUBTOTAL(9,H10:H206) | J7: =SUBTOTAL(9,J10:J206) | K7: =SUBTOTAL(9,K10:K206) | L7: =SUBTOTAL(9,L10:L206) | M7: =SUBTOTAL(9,M10:M206) | N7: =SUBTOTAL(9,N10:N206) | O7: =SUBTOTAL(9,O10:O206) | P7: =SUBTOTAL(9,P10:P206) | Q7: =SUBTOTAL(9,Q10:Q206) | ... AR7: =SUBTOTAL(9,AR10:AR206) | AT7: =SUBTOTAL(9,AT10:AT206) | AU7: =SUBTOTAL(9,AU10:AU206) | AV7: =SUBTOTAL(9,AV10:AV201) | AW7: =SUBTOTAL(9,AW10:AW195) | AX7: =SUBTOTAL(9,AX10:AX195) | AY7: =SUBTOTAL(9,AY10:AY195) | AZ7: =SUBTOTAL(9,AZ10:AZ195) | BA7: =SUBTOTAL(9,BA10:BA206) | BB7: =SUBTOTAL(9,BB10:BB206) | BC7: =SUBTOTAL(9,BC10:BC206) | BD7: =SUBTOTAL(9,BD10:BD202) | BE7: =SUBTOTAL(9,BE10:BE206) | BF7: =SUBTOTAL(9,BF10:BF206) | BG7: =SUBTOTAL(9,BG10:BG206) | BH7: =SUBTOTAL(9,BH10:BH206) | BI7: =SUBTOTAL(9,BI10:BI206) | BJ7: =SUBTOTAL(9,BJ10:BJ206) | BK7: =SUBTOTAL(9,BK10:BK206) | BL7: =SUBTOTAL(9,BL10:BL206) | ... GF7: =SUBTOTAL(9,GF10:GF206)
A8: NOTES | D8: OWNERS | E8: TOTAL
A9: OPEN — NO BASE OGL PROVED | D9: Fee mineral ownership open — source-limited cursory; no tract-level mineral quantum established.
C10: =E10*D$5 | E10: =SUM(G10:HY10)
C11: =E11*D$5 | E11: =SUM(G11:HY11)
C12: =E12*D$5 | E12: =SUM(G12:HY12)
C13: =E13*D$5 | E13: =SUM(G13:HY13)
C14: =E14*D$5 | E14: =SUM(G14:HY14)
C15: =E15*D$5 | E15: =SUM(G15:HY15)
C16: =E16*D$5 | E16: =SUM(G16:HY16)
C17: =E17*D$5 | E17: =SUM(G17:HY17)
C18: =E18*D$5 | E18: =SUM(G18:HY18)
C19: =E19*D$5 | E19: =SUM(G19:HY19)
C20: =E20*D$5 | E20: =SUM(G20:HY20)
C21: =E21*D$5 | E21: =SUM(G21:HY21)
... C55: =E55*D$5 | E55: =SUM(G55:HY55)
C56: =E56*D$5 | E56: =SUM(G56:HL56)
C57: =E57*D$5 | E57: =SUM(G57:HL57)
C58: =E58*D$5 | E58: =SUM(G58:HL58)
C59: =E59*D$5 | E59: =SUM(G59:HL59)
C60: =E60*D$5 | E60: =SUM(G60:HL60)
C61: =E61*D$5 | E61: =SUM(G61:HY61)
C62: =E62*D$5 | E62: =SUM(G62:HY62)
C63: =E63*D$5 | E63: =SUM(G63:HY63)
C64: =E64*D$5 | E64: =SUM(G64:HP64)
C65: =E65*D$5 | E65: =SUM(G65:HY65)
C66: =E66*D$5 | E66: =SUM(G66:HY66)
C67: =E67*D$5 | E67: =SUM(G67:HY67)
C68: =E68*D$5 | E68: =SUM(G68:HY68)
C69: =E69*D$5 | E69: =SUM(G69:HY69)
C70: =E70*D$5 | E70: =SUM(G70:HY70)
C71: =E71*D$5 | E71: =SUM(G71:HY71)
C72: =E72*D$5 | E72: =SUM(G72:HY72)
C73: =E73*D$5 | E73: =SUM(G73:HY73)
...

Sheet Tract 2
A1: TRACT 2 — SE/4 NE/4 AND E/2 SE/4 — 120.00 ACRES — FEE MINERAL CHAIN OPEN | E1: Instrument
A2: 2 | B2: TRACT | D2: SE/4 NE/4 and E/2 SE/4, containing 120.00 acres | E2: Image Number
B3: DESCRIPTION | E3: Book / Page
E4: Date
B5: TRACT ACRES | D5: 120 | E5: Conveyance
B6: BASE OGL | D6: Tract 2 | E6: =SUBTOTAL(9,E9:E205) | F6: SURFACE | I6: =IF(I7=0,"","RECHECK") | K6: =IF(K7=0,"","RECHECK") | M6: =IF(M7=0,"","RECHECK") | N6: =IF(N7=0,"","RECHECK") | O6: =IF(O7=0,"","RECHECK") | Q6: =IF(Q7=0,"","RECHECK") | R6: =IF(R7=0,"","RECHECK") | S6: =IF(S7=0,"","RECHECK") | T6: =IF(T7=0,"","RECHECK") | U6: =IF(U7=0,"","RECHECK") | V6: =IF(V7=0,"","RECHECK") | W6: =IF(W7=0,"","RECHECK") | X6: =IF(X7=0,"","RECHECK") | ... AA6: =IF(AA7=0,"","RECHECK") | AD6: =IF(AD7=0,"","RECHECK") | AE6: =IF(AE7=0,"","RECHECK") | AF6: =IF(AF7=0,"","RECHECK") | AG6: =IF(AG7=0,"","RECHECK") | AH6: =IF(AH7=0,"","RECHECK") | AI6: =IF(AI7=0,"","RECHECK") | AJ6: =IF(AJ7=0,"","RECHECK") | AK6: =IF(AK7=0,"","RECHECK") | ... GA6: =IF(GA7=0,"","RECHECK")
G7: =SUBTOTAL(9,G10:G206) | H7: =SUBTOTAL(9,H10:H206) | J7: =SUBTOTAL(9,J10:J206) | K7: =SUBTOTAL(9,K10:K206) | L7: =SUBTOTAL(9,L10:L206) | M7: =SUBTOTAL(9,M10:M206) | N7: =SUBTOTAL(9,N10:N206) | O7: =SUBTOTAL(9,O10:O206) | P7: =SUBTOTAL(9,P10:P206) | Q7: =SUBTOTAL(9,Q10:Q210) | R7: =SUBTOTAL(9,R10:R206) | S7: =SUBTOTAL(9,S10:S206) | T7: =SUBTOTAL(9,T10:T206) | U7: =SUBTOTAL(9,U10:U206) | V7: =SUBTOTAL(9,V10:V206) | W7: =SUBTOTAL(9,W10:W206) | X7: =SUBTOTAL(9,X10:X206) | Y7: =SUBTOTAL(9,Y10:Y206) | AA7: =SUBTOTAL(9,AA10:AA210) | AB7: =SUBTOTAL(9,AB10:AB207) | AC7: =SUBTOTAL(9,AC10:AC201) | AD7: =SUBTOTAL(9,AD10:AD201) | AE7: =SUBTOTAL(9,AE10:AE201) | AF7: =SUBTOTAL(9,AF10:AF201) | AG7: =SUBTOTAL(9,AG10:AG206) | AH7: =SUBTOTAL(9,AH10:AH202) | AI7: =SUBTOTAL(9,AI10:AI206) | AJ7: =SUBTOTAL(9,AJ10:AJ206) | AK7: =SUBTOTAL(9,AK10:AK206) | AL7: =SUBTOTAL(9,AL10:AL206) | AM7: =SUBTOTAL(9,AM10:AM206) | AN7: =SUBTOTAL(9,AN10:AN206) | AO7: =SUBTOTAL(9,AO10:AO206) | AP7: =SUBTOTAL(9,AP10:AP206) | ... GA7: =SUBTOTAL(9,GA10:GA206)
A8: NOTES | D8: OWNERS | E8: TOTAL
A9: OPEN — NO BASE OGL PROVED | D9: Fee mineral ownership open — source-limited cursory; no tract-level mineral quantum established.
C10: =E10*D$5 | E10: =SUM(G10:HT10)
C11: =E11*D$5 | E11: =SUM(G11:HT11)
C12: =E12*D$5 | E12: =SUM(G12:HT12)
C13: =E13*D$5 | E13: =SUM(G13:HT13)
C14: =E14*D$5 | E14: =SUM(G14:HT14)
C15: =E15*D$5 | E15: =SUM(G15:HT15)
C16: =E16*D$5 | E16: =SUM(G16:HT16)
C17: =E17*D$5 | E17: =SUM(G17:HT17)
C18: =E18*D$5 | E18: =SUM(G18:HT18)
C19: =E19*D$5 | E19: =SUM(G19:HP19)
C20: =E20*D$5 | E20: =SUM(G20:HP20)
C21: =E21*D$5 | E21: =SUM(G21:HT21)
C22: =E22*D$5 | E22: =SUM(G22:HT22)
C23: =E23*D$5 | E23: =SUM(G23:HT23)
C24: =E24*D$5 | E24: =SUM(G24:HT24)
C25: =E25*D$5 | E25: =SUM(G25:HT25)
C26: =E26*D$5 | E26: =SUM(G26:HT26)
C27: =E27*D$5 | E27: =SUM(G27:HT27)
C28: =E28*D$5 | E28: =SUM(G28:HT28)
C29: =E29*D$5 | E29: =SUM(G29:HT29)
C30: =E30*D$5 | E30: =SUM(G30:HT30)
C31: =E31*D$5 | E31: =SUM(G31:HT31)
C32: =E32*D$5 | E32: =SUM(G32:HT32)
... C34: =E34*D$5 | E34: =SUM(G34:HT34)
C35: =E35*D$5 | E35: =SUM(G35:HY35)
C36: =E36*D$5 | E36: =SUM(G36:HT36)
C37: =E37*D$5 | E37: =SUM(G37:HH37)
C38: =E38*D$5 | E38: =SUM(G38:HH38)
C39: =E39*D$5 | E39: =SUM(G39:HH39)
C40: =E40*D$5 | E40: =SUM(G40:HH40)
C41: =E41*D$5 | E41: =SUM(G41:HH41)
...

Sheet Tract 3
A1: TRACT 3 — NW/4 — 160.00 ACRES — FEE MINERAL CHAIN OPEN | E1: Instrument
A2: 3 | B2: TRACT | D2: NW/4, containing 160.00 acres | E2: Image Number
B3: DESCRIPTION | E3: Book / Page
E4: Date
B5: TRACT ACRES | D5: 160 | E5: Conveyance
B6: BASE OGL | D6: Tract 3 | E6: =SUBTOTAL(9,E9:E203) | F6: SURFACE | H6: =IF(H7=0,"","RECHECK") | K6: =IF(K7=0,"","RECHECK") | M6: =IF(M7=0,"","RECHECK") | N6: =IF(N7=0,"","RECHECK") | O6: =IF(O7=0,"","RECHECK") | P6: =IF(P7=0,"","RECHECK") | R6: =IF(R7=0,"","RECHECK") | T6: =IF(T7=0,"","RECHECK") | U6: =IF(U7=0,"","RECHECK") | V6: =IF(V7=0,"","RECHECK") | W6: =IF(W7=0,"","RECHECK") | X6: =IF(X7=0,"","RECHECK") | Y6: =IF(Y7=0,"","RECHECK") | Z6: =IF(Z7=0,"","RECHECK") | AA6: =IF(AA7=0,"","RECHECK") | ... AF6: =IF(AF7=0,"","RECHECK") | AI6: =IF(AI7=0,"","RECHECK") | AJ6: =IF(AJ7=0,"","RECHECK") | AK6: =IF(AK7=0,"","RECHECK") | AL6: =IF(AL7=0,"","RECHECK") | AM6: =IF(AM7=0,"","RECHECK") | AN6: =IF(AN7=0,"","RECHECK") | AO6: =IF(AO7=0,"","RECHECK") | AP6: =IF(AP7=0,"","RECHECK") | ... GA6: =IF(GA7=0,"","RECHECK")
G7: =SUBTOTAL(9,G10:G204) | I7: =SUBTOTAL(9,I10:I204) | J7: =SUBTOTAL(9,J10:J204) | L7: =SUBTOTAL(9,L10:L204) | M7: =SUBTOTAL(9,M10:M204) | N7: =SUBTOTAL(9,N10:N204) | O7: =SUBTOTAL(9,O10:O204) | P7: =SUBTOTAL(9,P10:P204) | Q7: =SUBTOTAL(9,Q10:Q204) | R7: =SUBTOTAL(9,R10:R208) | S7: =SUBTOTAL(9,S10:S208) | T7: =SUBTOTAL(9,T10:T204) | U7: =SUBTOTAL(9,U10:U204) | V7: =SUBTOTAL(9,V10:V204) | W7: =SUBTOTAL(9,W10:W204) | X7: =SUBTOTAL(9,X10:X204) | Y7: =SUBTOTAL(9,Y10:Y204) | Z7: =SUBTOTAL(9,Z10:Z204) | AA7: =SUBTOTAL(9,AA10:AA204) | ... AD7: =SUBTOTAL(9,AD10:AD204) | AF7: =SUBTOTAL(9,AF10:AF208) | AG7: =SUBTOTAL(9,AG10:AG212) | AH7: =SUBTOTAL(9,AH10:AH206) | AI7: =SUBTOTAL(9,AI10:AI206) | AJ7: =SUBTOTAL(9,AJ10:AJ206) | AK7: =SUBTOTAL(9,AK10:AK206) | AL7: =SUBTOTAL(9,AL10:AL204) | AM7: =SUBTOTAL(9,AM10:AM203) | AN7: =SUBTOTAL(9,AN10:AN204) | AO7: =SUBTOTAL(9,AO10:AO206) | AP7: =SUBTOTAL(9,AP10:AP204) | AQ7: =SUBTOTAL(9,AQ10:AQ204) | AR7: =SUBTOTAL(9,AR10:AR204) | AS7: =SUBTOTAL(9,AS10:AS204) | AT7: =SUBTOTAL(9,AT10:AT204) | AU7: =SUBTOTAL(9,AU10:AU204) | AV7: =SUBTOTAL(9,AV10:AV204) | AW7: =SUBTOTAL(9,AW10:AW204) | ... GA7: =SUBTOTAL(9,GA10:GA204)
A8: NOTES | D8: OWNERS | E8: TOTAL
A9: OPEN — NO BASE OGL PROVED | D9: Fee mineral ownership open — source-limited cursory; no tract-level mineral quantum established.
C10: =E10*D$5 | E10: =SUM(G10:HT10)
C11: =E11*D$5 | E11: =SUM(G11:HT11)
C12: =E12*D$5 | E12: =SUM(G12:HT12)
C13: =E13*D$5 | E13: =SUM(G13:HT13)
C14: =E14*D$5 | E14: =SUM(G14:HT14)
C15: =E15*D$5 | E15: =SUM(G15:HT15)
C16: =E16*D$5 | E16: =SUM(G16:HT16)
C17: =E17*D$5 | E17: =SUM(G17:HT17)
C18: =E18*D$5 | E18: =SUM(G18:HT18)
C19: =E19*D$5 | E19: =SUM(G19:HT19)
C20: =E20*D$5 | E20: =SUM(G20:HT20)
C21: =E21*D$5 | E21: =SUM(G21:HT21)
... C36: =E36*D$5 | E36: =SUM(G36:HT36)
C37: =E37*D$5 | E37: =SUM(G37:HY37)
C38: =E38*D$5 | E38: =SUM(G38:HT38)
C39: =E39*D$5 | E39: =SUM(G39:HH39)
C40: =E40*D$5 | E40: =SUM(G40:HH40)
C41: =E41*D$5 | E41: =SUM(G41:HH41)
C42: =E42*D$5 | E42: =SUM(G42:HH42)
C43: =E43*D$5 | E43: =SUM(G43:HH43)
C44: =E44*D$5 | E44: =SUM(G44:HT44)
C45: =E45*D$5 | E45: =SUM(G45:HP45)
C46: =E46*D$5 | E46: =SUM(G46:HT46)
C47: =E47*D$5 | E47: =SUM(G47:HT47)
C48: =E48*D$5 | E48: =SUM(G48:HT48)
C49: =E49*D$5 | E49: =SUM(G49:HT49)
C50: =E50*D$5 | E50: =SUM(G50:HT50)
C51: =E51*D$5 | E51: =SUM(G51:HT51)
C52: =E52*D$5 | E52: =SUM(G52:HT52)
C53: =E53*D$5 | E53: =SUM(G53:HT53)
C54: =E54*D$5 | E54: =SUM(G54:HT54)
...

Sheet Tract 4
A1: TRACT 4 — SW/4 — 160.00 ACRES — FEE MINERAL CHAIN OPEN | E1: Instrument
A2: 4 | B2: TRACT | D2: SW/4, containing 160.00 acres | E2: Image Number
B3: DESCRIPTION | E3: Book / Page
E4: Date
B5: TRACT ACRES | D5: 160 | E5: Conveyance
B6: BASE OGL | D6: Tract 4 | E6: =SUBTOTAL(9,E9:E186) | F6: SURFACE | I6: =IF(I7=0,"","RECHECK") | L6: =IF(L7=0,"","RECHECK") | M6: =IF(M7=0,"","RECHECK") | N6: =IF(N7=0,"","RECHECK") | O6: =IF(O7=0,"","RECHECK") | Q6: =IF(Q7=0,"","RECHECK") | R6: =IF(R7=0,"","RECHECK") | S6: =IF(S7=0,"","RECHECK") | T6: =IF(T7=0,"","RECHECK") | U6: =IF(U7=0,"","RECHECK") | V6: =IF(V7=0,"","RECHECK") | W6: =IF(W7=0,"","RECHECK") | X6: =IF(X7=0,"","RECHECK") | ... FN6: =IF(FN7=0,"","RECHECK")
G7: =SUBTOTAL(9,G10:G187) | H7: =SUBTOTAL(9,H10:H187) | J7: =SUBTOTAL(9,J10:J187) | K7: =SUBTOTAL(9,K10:K187) | L7: =SUBTOTAL(9,L10:L187) | M7: =SUBTOTAL(9,M10:M187) | N7: =SUBTOTAL(9,N10:N187) | O7: =SUBTOTAL(9,O10:O187) | P7: =SUBTOTAL(9,P10:P187) | Q7: =SUBTOTAL(9,Q10:Q187) | ... U7: =SUBTOTAL(9,U10:U187) | V7: =SUBTOTAL(9,V10:V190) | W7: =SUBTOTAL(9,W10:W187) | X7: =SUBTOTAL(9,X10:X187) | Y7: =SUBTOTAL(9,Y10:Y187) | Z7: =SUBTOTAL(9,Z10:Z187) | AA7: =SUBTOTAL(9,AA10:AA187) | AB7: =SUBTOTAL(9,AB10:AB187) | AC7: =SUBTOTAL(9,AC10:AC190) | AD7: =SUBTOTAL(9,AD10:AD190) | AE7: =SUBTOTAL(9,AE10:AE187) | AF7: =SUBTOTAL(9,AF10:AF187) | AG7: =SUBTOTAL(9,AG10:AG187) | AH7: =SUBTOTAL(9,AH10:AH187) | AI7: =SUBTOTAL(9,AI10:AI187) | AJ7: =SUBTOTAL(9,AJ10:AJ187) | AK7: =SUBTOTAL(9,AK10:AK187) | AL7: =SUBTOTAL(9,AL10:AL187) | ... FN7: =SUBTOTAL(9,FN10:FN187)
A8: NOTES | D8: OWNERS | E8: TOTAL
A9: OPEN — NO BASE OGL PROVED | D9: Fee mineral ownership open — source-limited cursory; no tract-level mineral quantum established.
E10: =SUM(G10:HG10)
E11: =SUM(G11:HG11)
E12: =SUM(G12:HG12)
E13: =SUM(G13:HG13)
E14: =SUM(G14:HG14)
E15: =SUM(G15:HG15)
E16: =SUM(G16:HH16)
E17: =SUM(G17:HH17)
E18: =SUM(G18:HH18)
E19: =SUM(G19:HH19)
E20: =SUM(G20:HH20)
E21: =SUM(G21:HG21)
E22: =SUM(G22:HG22)
E23: =SUM(G23:HG23)
E24: =SUM(G24:HG24)
E25: =SUM(G25:HG25)
E26: =SUM(G26:HG26)
E27: =SUM(G27:HK27)
E28: =SUM(G28:HK28)
E29: =SUM(G29:HK29)
E30: =SUM(G30:HG30)
E31: =SUM(G31:HG31)
C32: =E32*D$5 | E32: =SUM(G32:HG32)
C33: =E33*D$5 | E33: =SUM(G33:HG33)
C34: =E34*D$5 | E34: =SUM(G34:HG34)
C35: =E35*D$5 | E35: =SUM(G35:HG35)
C36: =E36*D$5 | E36: =SUM(G36:HG36)
C37: =E37*D$5 | E37: =SUM(G37:HG37)
C38: =E38*D$5 | E38: =SUM(G38:HG38)
C39: =E39*D$5 | E39: =SUM(G39:HG39)
C40: =E40*D$5 | E40: =SUM(G40:HG40)
...

Sheet Tract 5
A1: TRACT 5 — W/2 SE/4 — 80.00 ACRES — FEE MINERAL CHAIN OPEN | E1: Instrument
A2: 5 | B2: TRACT | D2: W/2 SE/4, containing 80.00 acres | E2: Image Number
B3: DESCRIPTION | E3: Book / Page
E4: Date
B5: TRACT ACRES | D5: 80 | E5: Conveyance
B6: BASE OGL | D6: Tract 5 | E6: =SUBTOTAL(9,E9:E203) | F6: SURFACE | I6: =IF(I7=0,"","RECHECK") | L6: =IF(L7=0,"","RECHECK") | M6: =IF(M7=0,"","RECHECK") | N6: =IF(N7=0,"","RECHECK") | O6: =IF(O7=0,"","RECHECK") | Q6: =IF(Q7=0,"","RECHECK") | R6: =IF(R7=0,"","RECHECK") | S6: =IF(S7=0,"","RECHECK") | T6: =IF(T7=0,"","RECHECK") | U6: =IF(U7=0,"","RECHECK") | V6: =IF(V7=0,"","RECHECK") | W6: =IF(W7=0,"","RECHECK") | X6: =IF(X7=0,"","RECHECK") | ... AE6: =IF(AE7=0,"","RECHECK") | AH6: =IF(AH7=0,"","RECHECK") | AI6: =IF(AI7=0,"","RECHECK") | AJ6: =IF(AJ7=0,"","RECHECK") | AK6: =IF(AK7=0,"","RECHECK") | AL6: =IF(AL7=0,"","RECHECK") | AM6: =IF(AM7=0,"","RECHECK") | AN6: =IF(AN7=0,"","RECHECK") | AO6: =IF(AO7=0,"","RECHECK") | ... FW6: =IF(FW7=0,"","RECHECK")
G7: =SUBTOTAL(9,G10:G204) | H7: =SUBTOTAL(9,H10:H204) | J7: =SUBTOTAL(9,J10:J204) | K7: =SUBTOTAL(9,K10:K204) | L7: =SUBTOTAL(9,L10:L204) | M7: =SUBTOTAL(9,M10:M204) | N7: =SUBTOTAL(9,N10:N204) | O7: =SUBTOTAL(9,O10:O204) | P7: =SUBTOTAL(9,P10:P204) | Q7: =SUBTOTAL(9,Q10:Q204) | ... U7: =SUBTOTAL(9,U10:U204) | V7: =SUBTOTAL(9,V10:V207) | W7: =SUBTOTAL(9,W10:W204) | X7: =SUBTOTAL(9,X10:X204) | Y7: =SUBTOTAL(9,Y10:Y204) | Z7: =SUBTOTAL(9,Z10:Z204) | AA7: =SUBTOTAL(9,AA10:AA204) | AB7: =SUBTOTAL(9,AB10:AB204) | AC7: =SUBTOTAL(9,AC10:AC207) | AE7: =SUBTOTAL(9,AE10:AE209) | AF7: =SUBTOTAL(9,AF10:AF212) | AG7: =SUBTOTAL(9,AG10:AG206) | AH7: =SUBTOTAL(9,AH10:AH206) | AI7: =SUBTOTAL(9,AI10:AI206) | AJ7: =SUBTOTAL(9,AJ10:AJ206) | AK7: =SUBTOTAL(9,AK10:AK207) | AL7: =SUBTOTAL(9,AL10:AL203) | AM7: =SUBTOTAL(9,AM10:AM207) | AN7: =SUBTOTAL(9,AN10:AN206) | AO7: =SUBTOTAL(9,AO10:AO204) | AP7: =SUBTOTAL(9,AP10:AP204) | AQ7: =SUBTOTAL(9,AQ10:AQ204) | AR7: =SUBTOTAL(9,AR10:AR204) | AS7: =SUBTOTAL(9,AS10:AS204) | AT7: =SUBTOTAL(9,AT10:AT204) | AU7: =SUBTOTAL(9,AU10:AU204) | AV7: =SUBTOTAL(9,AV10:AV204) | ... FW7: =SUBTOTAL(9,FW10:FW204)
A8: NOTES | D8: OWNERS | E8: TOTAL
A9: OPEN — NO BASE OGL PROVED | D9: Fee mineral ownership open — source-limited cursory; no tract-level mineral quantum established.
C10: =E10*D$5 | E10: =SUM(G10:HP10)
C11: =E11*D$5 | E11: =SUM(G11:HP11)
C12: =E12*D$5 | E12: =SUM(G12:HP12)
C13: =E13*D$5 | E13: =SUM(G13:HP13)
C14: =E14*D$5 | E14: =SUM(G14:HP14)
C15: =E15*D$5 | E15: =SUM(G15:HP15)
C16: =E16*D$5 | E16: =SUM(G16:HQ16)
C17: =E17*D$5 | E17: =SUM(G17:HQ17)
C18: =E18*D$5 | E18: =SUM(G18:HQ18)
C19: =E19*D$5 | E19: =SUM(G19:HQ19)
C20: =E20*D$5 | E20: =SUM(G20:HQ20)
C21: =E21*D$5 | E21: =SUM(G21:HP21)
C22: =E22*D$5 | E22: =SUM(G22:HP22)
C23: =E23*D$5 | E23: =SUM(G23:HP23)
C24: =E24*D$5 | E24: =SUM(G24:HP24)
C25: =E25*D$5 | E25: =SUM(G25:HP25)
C26: =E26*D$5 | E26: =SUM(G26:HP26)
C27: =E27*D$5 | E27: =SUM(G27:HT27)
C28: =E28*D$5 | E28: =SUM(G28:HT28)
C29: =E29*D$5 | E29: =SUM(G29:HT29)
C30: =E30*D$5 | E30: =SUM(G30:HP30)
C31: =E31*D$5 | E31: =SUM(G31:HP31)
C32: =E32*D$5 | E32: =SUM(G32:HP32)
C33: =E33*D$5 | E33: =SUM(G33:HP33)
C34: =E34*D$5 | E34: =SUM(G34:HP34)
C35: =E35*D$5 | E35: =SUM(G35:HP35)
C36: =E36*D$5 | E36: =SUM(G36:HP36)
C37: =E37*D$5 | E37: =SUM(G37:HY37)
C38: =E38*D$5 | E38: =SUM(G38:HS38)
C39: =E39*D$5 | E39: =SUM(G39:HH39)
C40: =E40*D$5 | E40: =SUM(G40:HH40)
...

Sheet WI 1
A1: OK48147.001.1 — DIVERSIFIED PATH; WI/NRI/NET ACRES OPEN; CARLSON 7H CARVE | E1: Instrument | H1: Confirmation of Division | I1: Confirmation of Merger | J1: Wellbore Sale | K1: Conveyance
A2: 1 | B2: TRACT | D2: All rights limited to the Cherokee Formation | E2: Image Number
B3: DESCRIPTION | E3: Book / Page | H3: =Runsheet!D2 | I3: =Runsheet!D3 | J3: =Runsheet!D4 | K3: =Runsheet!D5
E4: Date | H4: =Runsheet!F2 | I4: =Runsheet!F3 | J4: =Runsheet!F4 | K4: =Runsheet!F5
B5: TRACT ACRES | D5: 640 | E5: Conveyance | H5: IDENTITY PATH — OPEN | I5: IDENTITY PATH — OPEN | J5: WELLBORE CARVE | K5: WELLBORE CARVE
B6: BASE OGL | D6: Working Interest — source-limited | F6: SURFACE | K6: =IF(K7=0,"","RECHECK") | L6: =IF(L7=0,"","RECHECK") | M6: =IF(M7=0,"","RECHECK") | N6: =IF(N7=0,"","RECHECK") | O6: =IF(O7=0,"","RECHECK") | P6: =IF(P7=0,"","RECHECK") | R6: =IF(R7=0,"","RECHECK") | S6: =IF(S7=0,"","RECHECK") | T6: =IF(T7=0,"","RECHECK") | U6: =IF(U7=0,"","RECHECK") | V6: =IF(V7=0,"","RECHECK") | W6: =IF(W7=0,"","RECHECK") | X6: =IF(X7=0,"","RECHECK") | Y6: =IF(Y7=0,"","RECHECK") | Z6: =IF(Z7=0,"","RECHECK") | AB6: =IF(AB7=0,"","RECHECK") | AC6: =IF(AC7=0,"","RECHECK") | AD6: =IF(AD7=0,"","RECHECK") | AE6: =IF(AE7=0,"","RECHECK") | AF6: =IF(AF7=0,"","RECHECK") | AG6: =IF(AG7=0,"","RECHECK") | AH6: =IF(AH7=0,"","RECHECK") | AI6: =IF(AI7=0,"","RECHECK") | ... FQ6: =IF(FQ7=0,"","RECHECK")
G7: =SUBTOTAL(9,G10:G164) | H7: =SUBTOTAL(9,H10:H164) | I7: =SUBTOTAL(9,I10:I164) | J7: =SUBTOTAL(9,J10:J164) | K7: =SUBTOTAL(9,K10:K164) | L7: =SUBTOTAL(9,L10:L164) | M7: =SUBTOTAL(9,M10:M164) | N7: =SUBTOTAL(9,N10:N164) | ... FQ7: =SUBTOTAL(9,FQ10:FQ164)
A8: NOTES | D8: OWNERS
A9: OPEN — QUANTUM NOT DETERMINED | B9: OK48147.001.1 | D9: Diversified Production LLC — supported record-derived leasehold claimant
A10: IDENTITY PATH | B10: 2400/551–567 | D10: DP Sooner HoldCo LLC → Diversified Production LLC
A11: IDENTITY PATH | B11: 2395/415–464 | D11: DP Legacy Tapstone LLC → DP Sooner HoldCo LLC / Diversified ABS VI Upstream LLC
A12: BASE OGL OPEN | B12: 1697/236 | D12: Staghorn → Chesapeake assignment reference; not a proved base oil and gas lease
A13: WELLBORE CARVE OPEN | B13: 2183/174; 2185/639 | D13: Carlson 32-11-25 7H carve — intersection with OK48147 remains unmapped
C14: =E14*D$5 | E14: =SUM(G14:HJ14)
C15: =E15*D$5 | E15: =SUM(G15:HJ15)
C16: =E16*D$5 | E16: =SUM(G16:HJ16)
C17: =E17*D$5 | E17: =SUM(G17:HJ17)
C18: =E18*D$5 | E18: =SUM(G18:HJ18)
C19: =E19*D$5 | E19: =SUM(G19:HJ19)
C20: =E20*D$5 | E20: =SUM(G20:HJ20)
C21: =E21*D$5 | E21: =SUM(G21:HJ21)
C22: =E22*D$5 | E22: =SUM(G22:HJ22)
C23: =E23*D$5 | E23: =SUM(G23:HJ23)
C24: =E24*D$5 | E24: =SUM(G24:HJ24)
C25: =E25*D$5 | E25: =SUM(G25:HJ25)
... C163: =E163*D$5 | E163: =SUM(G163:HJ163)

Sheet WI 2
A1: NOT USED | B1: WI 2 | D1: No separate Springer Formation chain is supported within this Cherokee-limited cursory report | E1: Image Number
B2: DESCRIPTION | E2: Book / Page
E3: Date
B4: TRACT ACRES | E4: Conveyance
B5: STATUS | C5: N/A | D5: Working Interest 2 — NOT USED | E5: N/A | F5: OUT OF SCOPE | K5: =IF(K6=0,"","RECHECK") | L5: =IF(L6=0,"","RECHECK") | M5: =IF(M6=0,"","RECHECK") | N5: =IF(N6=0,"","RECHECK") | O5: =IF(O6=0,"","RECHECK") | P5: =IF(P6=0,"","RECHECK") | R5: =IF(R6=0,"","RECHECK") | S5: =IF(S6=0,"","RECHECK") | T5: =IF(T6=0,"","RECHECK") | U5: =IF(U6=0,"","RECHECK") | V5: =IF(V6=0,"","RECHECK") | W5: =IF(W6=0,"","RECHECK") | X5: =IF(X6=0,"","RECHECK") | Y5: =IF(Y6=0,"","RECHECK") | ... FQ5: =IF(FQ6=0,"","RECHECK")
G6: =SUBTOTAL(9,G9:G143) | H6: =SUBTOTAL(9,H9:H143) | I6: =SUBTOTAL(9,I9:I143) | J6: =SUBTOTAL(9,J9:J143) | K6: =SUBTOTAL(9,K9:K143) | L6: =SUBTOTAL(9,L9:L143) | M6: =SUBTOTAL(9,M9:M143) | N6: =SUBTOTAL(9,N9:N143) | ... FQ6: =SUBTOTAL(9,FQ9:FQ143)
A7: NOTES | D7: OWNERS
A9: NOT USED | D9: Unrelated inherited schedule removed; no separate Springer working-interest conclusion is stated.
C10: =E10*D$4 | E10: =SUM(G10:HJ10)
C11: =E11*D$4 | E11: =SUM(G11:HJ11)
C12: =E12*D$4 | E12: =SUM(G12:HJ12)
C13: =E13*D$4 | E13: =SUM(G13:HJ13)
C14: =E14*D$4 | E14: =SUM(G14:HJ14)
C15: =E15*D$4 | E15: =SUM(G15:HJ15)
C16: =E16*D$4 | E16: =SUM(G16:HJ16)
C17: =E17*D$4 | E17: =SUM(G17:HJ17)
C18: =E18*D$4 | E18: =SUM(G18:HJ18)
C19: =E19*D$4 | E19: =SUM(G19:HJ19)
C20: =E20*D$4 | E20: =SUM(G20:HJ20)
C21: =E21*D$4 | E21: =SUM(G21:HJ21)
... C142: =E142*D$4 | E142: =SUM(G142:HJ142)

Sheet Well 1
A1: Wells
A2: Well # | B2: API # | C2: Current Operator | D2: Well Name | E2: Formation | F2: Surface Location | G2: Bottom Hole Location | H2: Spud Date | I2: Perforated Interval(s) | J2: TD & TVD | K2: Spacing | L2: MU Order | M2: Type | N2: Completion Date | O2: Last Production | P2: Plugging | Q2: Allocation
A3: 1 | B3: 35-009-2192300 | C3: OPEN (regulatory) | D3: Carlson 32-11-25 7H | E3: OPEN | F3: Sec 32-11N-25W | G3: OPEN | M3: H | P3: OPEN | Q3: Wellbore carve 2183/174; correction 2185/639 → Linn Energy Holdings; API 35-009-2192300. OK48147 is absent from the carve exhibit (Garrett OK0005037-002 only). Overlap, current operator/status, orders, production and HBP remain NEEDS VERIFICATION. Source: _PROJECT_FILES\03_QA_AND_SUPPORT\FINAL_COMPLETION_PACKAGE\carlson_7h_carve_analysis.md
A4: 2 | B4: 35-009-20312 | C4: Complete Oil & Gas Services LLC | D4: Crook 1-32 | E4: Granite Wash Lower | F4: C W/2 NE/4 | G4: OPEN | M4: DRY | P4: DRY | Q4: OCC RBDMS filtered snapshot dated 2026-07-09 reports status code AC with well/status fields DRY/DRY — conflict preserved. Cause CD 59995 / Order 156126 dated 1979-08-06 was directly reviewed: it pools listed formations under all Section 32, names Leede as operator, and states a 180-day commencement condition. Current effect, production matching and HBP remain OPEN. Order source: _PROJECT_FILES\01_SOURCE_READ_ONLY\FROM_ROOT_00_EXTERNAL_EVIDENCE_INBOX\STAGING\ACCEPTED\OCC_PREEXISTING_ER_05\OCC_Order_156126_Cause_CD_59995_1979-08-06.pdf. Well source: _PROJECT_FILES\01_SOURCE_READ_ONLY\FROM_ROOT_00_EXTERNAL_EVIDENCE_INBOX\STAGING\ACCEPTED\OCC_PREEXISTING_ER_06_ctx\OCC_RBDMS_Section32_Filtered_2026-07-09.csv
A5: 3 | B5: 35-009-20605 | C5: SM ENERGY COMPANY | D5: Pearl 1-32 | E5: OPEN | F5: E/2 W/2 NE/4 | G5: OPEN | M5: GAS | P5: PLUGGED | Q5: OCC RBDMS filtered snapshot dated 2026-07-09 reports status code PA and PLUGGED. Regulatory context only — not present WI or HBP proof. Source: _PROJECT_FILES\01_SOURCE_READ_ONLY\FROM_ROOT_00_EXTERNAL_EVIDENCE_INBOX\STAGING\ACCEPTED\OCC_PREEXISTING_ER_06_ctx\OCC_RBDMS_Section32_Filtered_2026-07-09.csv
A6: 4 | B6: 35-009-00075 | C6: BP AMERICA PRODUCTION COMPANY | D6: CORA GARRETT #C-310 | E6: OPEN | F6: SE/4 SE/4 SE/4; 330' E, 330' S | G6: OPEN | K6: OPEN | L6: OPEN | M6: GAS | P6: PLUGGED | Q6: OCC snapshot code PA; regulatory context only — title, orders, production continuity and HBP NEED VERIFICATION. Source: _PROJECT_FILES\01_SOURCE_READ_ONLY\FROM_ROOT_00_EXTERNAL_EVIDENCE_INBOX\STAGING\ACCEPTED\OCC_PREEXISTING_ER_06_ctx\OCC_RBDMS_Section32_Filtered_2026-07-09.csv
A7: 5 | B7: 35-009-20738 | C7: LEEDE OIL & GAS INC | D7: LEGRAND #1-32 | E7: OPEN | F7: NW/4 SE/4 NW/4; 1,900' W, 1,220' S | G7: OPEN | K7: OPEN | L7: OPEN | M7: DRY | P7: PLUGGED | Q7: OCC snapshot code PA; regulatory context only — title, orders, production continuity and HBP NEED VERIFICATION. Source: _PROJECT_FILES\01_SOURCE_READ_ONLY\FROM_ROOT_00_EXTERNAL_EVIDENCE_INBOX\STAGING\ACCEPTED\OCC_PREEXISTING_ER_06_ctx\OCC_RBDMS_Section32_Filtered_2026-07-09.csv
A8: 6 | B8: 35-009-21072 | C8: BCE-MACH II LLC | D8: JGL #1-32 | E8: OPEN | F8: SW/4 NW/4 SW/4 NE/4; 240' W, 740' S | G8: OPEN | K8: OPEN | L8: OPEN | M8: GAS | P8: GAS | Q8: OCC snapshot code AC; regulatory context only — operator role is not title ownership and HBP NEEDS VERIFICATION. Source: _PROJECT_FILES\01_SOURCE_READ_ONLY\FROM_ROOT_00_EXTERNAL_EVIDENCE_INBOX\STAGING\ACCEPTED\OCC_PREEXISTING_ER_06_ctx\OCC_RBDMS_Section32_Filtered_2026-07-09.csv
A9: 7 | B9: 35-009-21085 | C9: BCE-MACH II LLC | D9: HANKS CROOK #1-32 | E9: OPEN | F9: C S/2 NE/4; 1,320' W, 660' S | G9: OPEN | K9: OPEN | L9: OPEN | M9: GAS | P9: GAS | Q9: OCC snapshot code AC; regulatory context only — operator role is not title ownership and HBP NEEDS VERIFICATION. Source: _PROJECT_FILES\01_SOURCE_READ_ONLY\FROM_ROOT_00_EXTERNAL_EVIDENCE_INBOX\STAGING\ACCEPTED\OCC_PREEXISTING_ER_06_ctx\OCC_RBDMS_Section32_Filtered_2026-07-09.csv
A10: 8 | B10: 35-009-21166 | C10: VASTAR RESOURCES INC | D10: CROOK-LEGRAND #1-32 | E10: OPEN | F10: S/2 N/2 N/2 SE/4 | G10: OPEN | K10: OPEN | L10: OPEN | M10: NT | P10: PLUGGED | Q10: OCC snapshot code PA; regulatory context only — title, orders, production continuity and HBP NEED VERIFICATION. Source: _PROJECT_FILES\01_SOURCE_READ_ONLY\FROM_ROOT_00_EXTERNAL_EVIDENCE_INBOX\STAGING\ACCEPTED\OCC_PREEXISTING_ER_06_ctx\OCC_RBDMS_Section32_Filtered_2026-07-09.csv
A11: 9 | B11: 35-009-21236 | C11: BCE-MACH II LLC | D11: LEGRAND #1-32 | E11: OPEN | F11: NW/4 NE/4 SE/4 SW/4; 2,200' W, 1,150' S | G11: OPEN | K11: OPEN | L11: OPEN | M11: GAS | P11: GAS | Q11: Distinct API from 35-009-20738. OCC snapshot code AC; regulatory context only — HBP NEEDS VERIFICATION. Source: _PROJECT_FILES\01_SOURCE_READ_ONLY\FROM_ROOT_00_EXTERNAL_EVIDENCE_INBOX\STAGING\ACCEPTED\OCC_PREEXISTING_ER_06_ctx\OCC_RBDMS_Section32_Filtered_2026-07-09.csv
A12: 10 | B12: 35-009-21245 | C12: BP AMERICA PRODUCTION COMPANY | D12: KATIE #1-32 | E12: OPEN | F12: N/2 N/2 S/2 NW/4 | G12: OPEN | K12: OPEN | L12: OPEN | M12: NT | P12: OTHER | Q12: OCC snapshot code EX; regulatory context only — title, orders, production continuity and HBP NEED VERIFICATION. Source: _PROJECT_FILES\01_SOURCE_READ_ONLY\FROM_ROOT_00_EXTERNAL_EVIDENCE_INBOX\STAGING\ACCEPTED\OCC_PREEXISTING_ER_06_ctx\OCC_RBDMS_Section32_Filtered_2026-07-09.csv
A13: 11 | B13: 35-009-21258 | C13: BCE-MACH II LLC | D13: LEGRAND #2-32 | E13: OPEN | F13: N/2 N/2 S/2 NW/4; 1,320' W, 1,070' S | G13: OPEN | K13: OPEN | L13: OPEN | M13: GAS | P13: GAS | Q13: OCC snapshot code AC; regulatory context only — operator role is not title ownership and HBP NEEDS VERIFICATION. Source: _PROJECT_FILES\01_SOURCE_READ_ONLY\FROM_ROOT_00_EXTERNAL_EVIDENCE_INBOX\STAGING\ACCEPTED\OCC_PREEXISTING_ER_06_ctx\OCC_RBDMS_Section32_Filtered_2026-07-09.csv
A14: 12 | B14: 35-009-21391 | C14: BCE-MACH II LLC | D14: TWIN #1-32 | E14: OPEN | F14: NW/4 NE/4 SE/4 SW/4; 2,000' W, 1,150' S | G14: OPEN | K14: OPEN | L14: OPEN | M14: GAS | P14: GAS | Q14: OCC snapshot code AC; regulatory context only — operator role is not title ownership and HBP NEEDS VERIFICATION. Source: _PROJECT_FILES\01_SOURCE_READ_ONLY\FROM_ROOT_00_EXTERNAL_EVIDENCE_INBOX\STAGING\ACCEPTED\OCC_PREEXISTING_ER_06_ctx\OCC_RBDMS_Section32_Filtered_2026-07-09.csv

Sheet IMAGE_INVENTORY_0001_0500
A1: Source position | B1: Exact filename | C1: Drive file ID or link | D1: Opened visually | E1: Review status | F1: Image quality | G1: Document-group ID | H1: First page or continuation | I1: Relevant to Section 32 | J1: Relevant to Diversified | K1: Extraction status | L1: Notes
A2: 1 | B2: 0001.jpg | C2: https://drive.google.com/file/d/1mY8YO0k5KwvNxInc1hTdEGBNg3OYM4Bk/view | D2: YES | E2: reviewed_instrument_page | F2: fair-to-good | G2: B01-G001 | H2: first_or_single_page | I2: True | J2: False | K2: extracted | L2: Visually inspected; OCR used only as an aid. Multiple groups listed where the page contains separate instruments.
A3: 2 | B3: 0002.jpg | C3: https://drive.google.com/file/d/1siMKLe61gqsnKVcTG_L-TYKk-21epkWE/view | D3: YES | E3: reviewed_instrument_page | F3: fair-to-good | G3: B01-G002 | H3: first_or_single_page | I3: True | J3: False | K3: extracted | L3: Visually inspected; OCR used only as an aid. Multiple groups listed where the page contains separate instruments.
A4: 3 | B4: 0003.jpg | C4: https://drive.google.com/file/d/19SOFVjSNOE5Kpc9dO8iXWtNAZ3jHkOjv/view | D4: YES | E4: reviewed_instrument_page | F4: fair-to-good | G4: B01-G003 | H4: first_or_single_page | I4: True | J4: False | K4: extracted | L4: Visually inspected; OCR used only as an aid. Multiple groups listed where the page contains separate instruments.
A5: 4 | B5: 0004.jpg | C5: https://drive.google.com/file/d/1GjILIn9DFyeHP-iu0xV-aY5j6f_56eDN/view | D5: YES | E5: reviewed_instrument_page | F5: fair-to-good | G5: B01-G004; B01-G005 | H5: first_or_single_page | I5: True | J5: False | K5: partial_or_multi_instrument_extracted | L5: Visually inspected; OCR used only as an aid. Multiple groups listed where the page contains separate instruments.
A6: 5 | B6: 0005.jpg | C6: https://drive.google.com/file/d/112DMLh6DeA8ECaVqN3_DLqrXjuKs6ECt/view | D6: YES | E6: reviewed_instrument_page | F6: fair-to-good | G6: B01-G006; B01-G007 | H6: first_or_single_page | I6: True | J6: False | K6: partial_or_multi_instrument_extracted | L6: Visually inspected; OCR used only as an aid. Multiple groups listed where the page contains separate instruments.
A7: 6 | B7: 0006.jpg | C7: https://drive.google.com/file/d/1BiI5GbY3m4ojKIPvyzApAwtu5L-tCXcc/view | D7: YES | E7: reviewed_instrument_page | F7: fair-to-good | G7: B01-G008; B01-G009 | H7: first_or_single_page | I7: True | J7: False | K7: partial_or_multi_instrument_extracted | L7: Visually inspected; OCR used only as an aid. Multiple groups listed where the page contains separate instruments.
A8: 7 | B8: 0007.jpg | C8: https://drive.google.com/file/d/1EzKyARydVQaTjiLzbxK5b_63_J-IDjor/view | D8: YES | E8: duplicate | F8: fair-to-good | G8: B01-G010 | H8: first_or_single_page | I8: True | J8: False | K8: duplicate_linked | L8: Duplicate exposure of 0008.jpg.
A9: 8 | B9: 0008.jpg | C9: https://drive.google.com/file/d/14ab5mC2Rs-CGpLmamoxuosbqhdpRxn4A/view | D9: YES | E9: reviewed_instrument_page | F9: fair-to-good | G9: B01-G010 | H9: first_or_single_page | I9: True | J9: False | K9: extracted | L9: Visually inspected; OCR used only as an aid. Multiple groups listed where the page contains separate instruments.
A10: 9 | B10: 0009.jpg | C10: https://drive.google.com/file/d/1zS4kMxokKsha7PQxemTfaaBSHMwqg0bY/view | D10: YES | E10: reviewed_instrument_page | F10: fair-to-good | G10: B01-G011 | H10: first_or_single_page | I10: True | J10: False | K10: extracted | L10: Visually inspected; OCR used only as an aid. Multiple groups listed where the page contains separate instruments.
A11: 10 | B11: 0010.jpg | C11: https://drive.google.com/file/d/1cXtfmzroHg-7uzj7PZh3bdKNao327mgw/view | D11: YES | E11: continuation_or_mixed_page | F11: fair-to-good | G11: B01-G011 | H11: continuation | I11: True | J11: False | K11: partial_or_multi_instrument_extracted | L11: Visually inspected; OCR used only as an aid. Multiple groups listed where the page contains separate instruments.
