Workbook
Name Check1_1: #REF!
Name Check2_1: #REF!
Name Check3_1: #REF!
Name Check4_1: #REF!
Name check5: '[1]Tract Plat Map '!$C$65
Name Check5_1: #REF!
Name Check6_1: #REF!
Name Check7_1: #REF!
Name oijjjojoijpojpoi: #REF!
Name Plat_LastSaved: #REF!
Name Test: #REF!
Name Test4: #REF!
Name XXXXXX: '[2]Well Plat Map '!$B$60

Sheet Overview
D3: Prospect | Q3: 25-004
C5: Section | H5: 31 | L5: Township | R5: 12N | Y5: Range | AC5: 24W
D7: County | H7: Roger Mills | U7: State | X7: Oklahoma
B9: Containing 640.00 acres, more or less
Y14: Tract 1
M18: Tract 4
U22: Tract 2 | AC22: Tract 3
E26: Tract 5
AC30: Tract 7
M34: Tract 6
U36: Tract 8
B44: ATTACHMENTS: | I44: OWNERSHIP REPORT DATED: | Y44: LAST ENTRY:
I46: TITLE OPINION UPDATE DATED: | Y46: LAST ENTRY:
G48: x | I48: CURSORY REPORT DATED: | S48: 6/16/2026 | Y48: LAST ENTRY: | AC48: 2704/142
I50: COUNTY CERTIFICATION DATE:
B52: REMARKS:
B53: REPORT IS A CURSORY REPORT
B56: EXAMINER: | F56: RG

Sheet Title 
B4: TRACT 1: | C4: N/2 NE/4
B5: Containing: | C5: 80 acres, more or less
B7: Mineral Owner | C7: Net Acres | D7: OGL No. | E7: Royalty | F7: Expiration | G7: Comments
B8: Gena Mitchell a/k/a Gena Williams a/k/a Gena Moore | C8: TBD | D8: 2702/0505 | E8: Not stated | F8: Recent Silver Oak lease | G8: N/2 NE/4, SE/4 NE/4; lease terms and ownership require full image.
B9: Mitchell-Buonaccorsi Living Trust trustees | C9: TBD | D9: 2693/0337 | E9: Not stated | F9: Recent Silver Oak lease | G9: N/2 NE/4, SE/4 NE/4; full lease image needed.
B10: Keri Lee Daigle Tucker Trust | C10: TBD | D10: 2697/0520 | E10: Not stated | F10: PDF expanded legal | G10: S31 T12N R24W N2 NE SW; NE SE; SE NE from PDF page 88.
B11: Ronald Paul Dold | C11: TBD | D11: 2697/0524 | E11: Not stated | F11: PDF expanded legal | G11: Covers E2 NW/N2/NE and SW tracts per PDF page 88; full lease needed.
B12: Mark Ashley Daigle Trust | C12: TBD | D12: 2693/0349 | E12: Not stated | F12: Recent Silver Oak lease | G12: SE/4 NE/4, NE/4 SE/4; full lease needed.
B13: Kevin Warner Johnson Trust | C13: TBD | D13: 2693/0345 | E13: Not stated | F13: Recent Silver Oak lease | G13: SE/4 NE/4, NE/4 SE/4; full lease needed.
B14: Carrie Leeann Mitchell / Nancy Susan Mitchell | C14: TBD | D14: 001608/0541; 001608/0543 | E14: Not stated | F14: Historic EOG lease rows | G14: Historic PDF page 24 additions; release/HBP not determined.
B16: REPORT TOTAL | C16: =SUM(C8:C15) -> 0
B17: TOTAL | C17: =SUM(C8:C15) -> 0
B20: TRACT 2: | C20: SW/4 NE/4
B21: Containing: | C21: 40 acres, more or less
B23: Mineral Owner | C23: Net Acres | D23: OGL No. | E23: Royalty | F23: Expiration | G23: Comments
B24: EDR, LLC -> Del Monte Royalty Partners, LLC PO BOX 18876, Oklahoma City, OK | C24: TBD | D24: 2625/0233 | E24: N/A | F24: Mineral deed | G24: SW/4 NE/4; exact fraction/net acres not in index.
B25: EDR, LLC -> Okki Industries, LLC PO BOX 54859, Oklahoma City, OK | C25: TBD | D25: 2625/0231 | E25: N/A | F25: Mineral deed | G25: SW/4 NE/4; exact fraction/net acres not in index.
B26: Greystone Energy & Minerals -> Cardinal Land Co. / EDR | C26: TBD | D26: 2481/0287 | E26: N/A | F26: Mineral deed | G26: SW/4 NE/4; full deed needed.
B27: Paul R. Deutsch / Deborah A. Deutsch | C27: TBD | D27: 2561/0142 | E27: N/A | F27: Address/notice item | G27: SW/4 NE/4; no conveyance inferred.
B28: Matthew Lucas / Katie Lucas | C28: TBD | D28: 2541/0100; 2488/0370 | E28: N/A | F28: Mortgage/release match needed | G28: SE/4 SW/4/Lot 4 partial; collateral/release scope TBD.
B30: REPORT TOTAL | C30: =SUM(C24:C29) -> 0
B31: TOTAL | C31: =SUM(C24:C29) -> 0
B34: TRACT 3: | C34: SE/4 NE/4
B35: Containing: | C35: 40 acres, more or less
B37: Mineral Owner | C37: Net Acres | D37: OGL No. | E37: Royalty | F37: Expiration | G37: Comments
B38: Gena Mitchell a/k/a Williams / Gena W. Moore | C38: TBD | D38: 2702/0505 | E38: 3/16 (0.1875) | F38: Top lease; 5-yr primary; exp 02/11/2031 (springs on prior-lease termination) | G38: N/2 NE/4, SE/4 NE/4; lease terms and ownership require full image. TOP LEASE subordinate to prior 2004-era lease; springs on its termination. Prior Lease: (Mitchell family) to R. Michael Lortz, dtd 01/14/2004, Bk 1736. Term resolved from non-watermarked page-1 image, OKCountyRecords API print 6/12/2026.
B39: Mitchell-Buonaccorsi Living Trust trustees | C39: TBD | D39: 2693/0337 | E39: 3/16 (0.1875) | F39: Top lease; 3-yr primary; exp 02/23/2029 (springs on prior-lease termination) | G39: N/2 NE/4, SE/4 NE/4; full lease image needed. TOP LEASE subordinate to prior 2004-era lease; springs on its termination. Prior Lease: Carrie Leeann Mitchell to R. Michael Lortz, dtd 01/14/2004, Bk 1736 Pg 0594. Term resolved from non-watermarked page-1 image, OKCountyRecords API print 6/12/2026.
B40: Keri Lee Daigle Tucker Trust | C40: TBD | D40: 2697/0520 | E40: 3/16 (0.1875) | F40: Top lease; 5-yr primary term; exp 02/17/2031 | G40: S31 T12N R24W N2 NE SW; NE SE; SE NE from PDF page 88. TOP LEASE subordinate to prior 2004-era lease; springs on its termination. Prior Lease: Sorenson Daigle/Johnson trustees to R. Michael Lortz (2004).
B41: Ronald Paul Dold | C41: TBD | D41: 2697/0524 | E41: 3/16 (0.1875) | F41: Top lease; 3-yr primary term; exp 03/31/2029 | G41: Covers E2 NW/N2/NE and SW tracts per PDF page 88; full lease needed. TOP LEASE subordinate to prior 2004-era lease; springs on its termination. Prior Lease: Nancy S. Mitchell to R. Michael Lortz, dtd 01/14/2004.
B42: Mark Ashley Daigle Trust | C42: TBD | D42: 2693/0349 | E42: 3/16 (0.1875) | F42: Top lease; 5-yr primary; exp 02/23/2031 (springs on prior-lease termination) | G42: SE/4 NE/4, NE/4 SE/4; full lease needed. TOP LEASE subordinate to prior 2004-era lease; springs on its termination. Prior Lease: Sorenson Oil and Gas Trust (Daigle/Johnson, TTEEs) to N/G Discovery, L.L.C.. Term resolved from non-watermarked page-1 image, OKCountyRecords API print 6/12/2026.
B43: Kevin Warner Johnson Trust | C43: TBD | D43: 2693/0345 | E43: 3/16 (0.1875) | F43: Top lease; 5-yr primary; exp 02/27/2031 (springs on prior-lease termination) | G43: SE/4 NE/4, NE/4 SE/4; full lease needed. TOP LEASE subordinate to prior 2004-era lease; springs on its termination. Prior Lease: Sorenson Oil and Gas Trust (Daigle/Johnson, TTEEs) to R. Michael Lortz, dtd 2004. Term resolved from non-watermarked page-1 image, OKCountyRecords API print 6/12/2026.
B44: Carrie Leeann Mitchell / Nancy Susan Mitchell | C44: TBD | D44: 001608/0541; 001608/0543 | E44: Not stated | F44: Historic EOG lease rows | G44: Historic PDF page 24 additions; release/HBP not determined.
B46: REPORT TOTAL | C46: =SUM(C38:C45) -> 0
B47: TOTAL | C47: =SUM(C38:C45) -> 0
B50: TRACT 4: | C50: E/2 NW/4
B51: Containing: | C51: 80 acres, more or less
B53: Mineral Owner | C53: Net Acres | D53: OGL No. | E53: Royalty | F53: Expiration | G53: Comments
B54: Ronald Paul Dold | C54: TBD | D54: 2697/0524 | E54: 3/16 (0.1875) | F54: Top lease; 3-yr primary term; exp 03/31/2029 | G54: Covers E2 NW/N2/NE and SW tracts per PDF page 88; full lease needed. TOP LEASE subordinate to prior 2004-era lease; springs on its termination. Prior Lease: Nancy S. Mitchell to R. Michael Lortz, dtd 01/14/2004.
B55: Colt Development / Roca Development -> Dustin Deal, LLC | C55: TBD | D55: 2426/0154 | E55: N/A | F55: Mineral deed | G55: E/2 NW/4; exact quantum not stated.
B56: Cindy Lou Vignal Trustee -> Gary Wayne Vignal Trustee | C56: TBD | D56: 2406/0228 | E56: N/A | F56: Quit Claim Mineral Deed | G56: E/2 NW/4; full deed needed.
...

Sheet PLAT
B2: SECTION 31 — T12N R24W, Roger Mills County, OK
B3: Tract / Aliquot Plat — nominal 40-acre quarter-quarter diagram (North up). Not a survey.
C5: N ↑
B6: W | C6: NW/4 NW/4 Tract 5 | E6: NE/4 NW/4 Tract 4 | G6: NW/4 NE/4 Tract 1 | I6: NE/4 NE/4 Tract 1 | K6: E
C9: SW/4 NW/4 Tract 5 | E9: SE/4 NW/4 Tract 4 | G9: SW/4 NE/4 Tract 2 | I9: SE/4 NE/4 Tract 3
C12: NW/4 SW/4 Tract 6 | E12: NE/4 SW/4 NOT ASSIGNED | G12: NW/4 SE/4 Tract 8 | I12: NE/4 SE/4 Tract 7
C15: SW/4 SW/4 Tract 6 | E15: SE/4 SW/4 Tract 5 (part) | G15: SW/4 SE/4 Tract 8 | I15: SE/4 SE/4 Tract 8
C18: S
B20: LEGEND
C21: Tract | D21: Legal description | G21: Nom. ac. | H21: Notes
C22: Tract 1 | D22: N/2 NE/4 | G22: 80
C23: Tract 2 | D23: SW/4 NE/4 | G23: 40
C24: Tract 3 | D24: SE/4 NE/4 | G24: 40
C25: Tract 4 | D25: E/2 NW/4 | G25: 80
C26: Tract 5 | D26: NW/4 partial (W/2, Lots 1 & 4) + SE/4 SW/4 partial | G26: Irregular — VERIFY | H26: Boundary section; W & S tiers are government lots with non-40 acreage.
C27: Tract 6 | D27: W/2 SW/4 | G27: 80 (nom.) | H27: SW tier lotted — confirm acreage vs plat.
C28: Tract 7 | D28: NE/4 SE/4 | G28: 40
C29: Tract 8 | D29: W/2 SE/4, SE/4 SE/4 | G29: 120 (nom.)
C30: — | D30: NE/4 SW/4 | G30: 40 | H30: NOT in any subject tract per current legals — verify (may fall in lots).
B32: Diagram derived from the tract legal descriptions on the Title sheet (data already in this workbook). Aliquot positions are nominal; Section 31 is a township-boundary section, so the west and south tiers are government lots whose true acreage differs from 40. Not a survey — confirm boundaries and acreage against the recorded plat/survey.
B35: Aerial / plat reference — attach recorded plat/survey image here when available.

Sheet OGLs
A1: OGL # | B1: LH | C1: Image # | D1: Instrument | E1: Bk./Pg. | F1: Execution Date | G1: Filing Date | H1: Grantor | I1: Grantee | J1: Legal Description | K1: Misc. Notes | L1: Term | M1: Gross Acres | N1: Tracts | O1: Exp Date | P1: Net Mineral Acres | Q1: Royalty | R1: Depth Clause | S1: Option to Extend | T1: No Warranty Clause | U1: Top Lease Clause | V1: Notes
A2: 29 | D2: Oil and Gas Lease | E2: 4/61 | F2: 6333 | G2: 6333 | H2: H. E. Rupp, L. M. Rupp | I2: Reo Oil and Gas Company | J2: All of 31-12N-24W aol
A3: 30 | D3: Oil and Gas Lease | E3: 4/64 | F3: 6333 | G3: 6333 | H3: M. Hambrook | I3: Reo Oil and Gas Company | J3: All of 31-12N-24W
A4: 33 | D4: Oil and Gas Lease | E4: 4/401 | F4: 7090 | G4: 7090 | H4: Susie Danforth, W. C. Danforth | I4: John R. Williams | J4: All of 31-12N-24W
A5: 34 | D5: Oil and Gas Lease | E5: 4/445 | F5: 7116 | G5: 7116 | H5: H. E. Rupp, Lulu M. Rupp | I5: J. G. Queman | J5: All of 31-12N-24W
A6: 35 | D6: Oil and Gas Lease | E6: 4/556 | F6: 7341 | G6: 7341 | H6: Margaret V. Black, William G. Black | I6: W. E. Thomas | J6: All of 31-12N-24W aol
A7: 31 | D7: Oil and Gas Lease | E7: 5/320 | F7: 6399 | G7: 6399 | H7: Claude J. Mcguire, Herbert E. Mcguire | I7: Empire Gas and Fuel Company | J7: All of 31-12N-24W
A8: 32 | D8: Oil and Gas Lease | E8: 5/332 | F8: 6399 | G8: 6399 | H8: C. S. Repass, Sarah Repass | I8: Empire Gas and Fuel Company | J8: All of 31-12N-24W
A9: 36 | D9: Oil and Gas Lease | E9: 6/484 | F9: 8513 | G9: 8513 | H9: E. T. Gamble, Zella Gamble | I9: Calvin M. Rosser | J9: All of 31-12N-24W
A10: 37 | D10: Oil and Gas Lease | E10: 8/649 | F10: 11164 | G10: 11164 | H10: Louis E. Jaques, Virginia Jaques | I10: Roy M. Johnson | J10: All of 31-12N-24W aol
A11: 39 | D11: Oil and Gas Lease | E11: 9/30 | F11: 11177 | G11: 11177 | H11: Mark Hambrook | I11: Roy M. Johnson | J11: All of 31-12N-24W
A12: 38 | D12: Oil and Gas Lease | E12: 9/32 | F12: 11174 | G12: 11174 | H12: Lee Aulbert, Mollie Aulbert | I12: Roy M. Johnson | J12: All of 31-12N-24W
A13: 40 | D13: Oil and Gas Lease | E13: 9/62 | F13: 11223 | G13: 11223 | H13: Eula Bain, William C. Bain | I13: Roy M. Johnson | J13: All of 31-12N-24W
... A311: 204 | D311: Oil and Gas Lease | E311: 1676/377 | F311: 37347 | G311: 37372 | H311: Myron V. Slobin | I311: Chesapeake Exploration Ltd. PTN | J311: NW/4 SE/4, S/2 SE/4, SW/4 NE/4 of 31-12N-24W
A312: 1 | D312: Oil and Gas Lease | E312: 1676/377 | F312: 37347 | G312: 37372 | H312: Myron V. Slobin | I312: Chesapeake Exploration, Ltd. Partnership | J312: NW/4 SE/4, S/2 SE/4, SW/4 NE/4 of 31-12N-24W | L312: 36 | M312: 160 | O312: 38443 | Q312: 0.25 | S312: F
A313: 205 | D313: Oil and Gas Lease | E313: 1676/379 | F313: 37354 | G313: 37372 | H313: Paul A, Prsnl Repres Albert | I313: Chesapeake Exploration Ltd. PTN | J313: SE/4 SW/4 of 31-12N-24W
A314: 2 | D314: Oil and Gas Lease | E314: 1676/379 | F314: 37354 | G314: 37372 | H314: Paul A, Personal Rep. Albert | I314: Chesapeake Exploration, Ltd. Partnership | J314: SE/4 SW/4 of 31-12N-24W | L314: 36 | M314: 40 | O314: 38450 | Q314: 0.25 | S314: F
A315: 1 | D315: Lease | E315: 1676/377 | F315: 37347 | G315: 37372 | H315: Myron V. Slobin | I315: Chesapeake Exploration Ltd. Ptn | J315: 31-12N-24W | L315: 36 | M315: 160 | O315: 38443 | Q315: 0.25 | S315: F
A316: 2 | D316: Lease | E316: 1676/379 | F316: 37354 | G316: 37372 | H316: Paul A. Prsnl Rep Albert | I316: Chesapeake Exploration Ltd. Ptn | J316: 31-12N-24W | L316: 36 | M316: 40 | O316: 38450 | Q316: 0.25 | S316: F
A317: 214 | D317: Oil and Gas Lease | E317: 1677/512 | F317: 37384 | G317: 37389 | H317: Hayhurst Oil Properties, Inc. | I317: Fleshman Agency, Inc. | J317: E/2 NW/4, N/2 NE/4 SW/4, NE/4 SE/4, SE/4 NE/4 of 31-12N-24W
A318: 7 | D318: Oil and Gas Lease | E318: 1677/512 | F318: 37384 | G318: 37389 | H318: Hayhurst Oil Properties, Inc. | I318: Fleshman Agency, Inc. | J318: E/2 NW/4, N/2 NE/4 SW/4, NE/4 SE/4, SE/4 NE/4 of 31-12N-24W | L318: 12 | M318: 180 | O318: 37749 | Q318: 0.25 | S318: F
A319: 210 | D319: Oil and Gas Lease | E319: 1677/516 | F319: 37364 | G319: 37389 | H319: Lyle T. Ibeling | I319: Chesapeake Exploration Ltd. PTN | J319: NW/4 SE/4, S/2 SE/4, SW/4 NE/4 of 31-12N-24W
A320: 5 | D320: Oil and Gas Lease | E320: 1677/516 | F320: 37364 | G320: 37389 | H320: Lyle T. Ibeling | I320: Chesapeake Exploration Co., Ltd. Partnership | J320: NW/4 SE/4, S/2 SE/4, SW/4 NE/4 of 31-12N-24W | L320: 36 | M320: 160 | O320: 38460 | Q320: 0.25 | S320: F
A321: 208 | D321: Oil and Gas Lease | E321: 1677/533 | F321: 37361 | G321: 37389 | H321: David S. Silverberg | I321: EOG Resources Inc. | J321: NW/4 SE/4, S/2 SE/4, SW/4 NE/4 of 31-12N-24W
A322: 4 | D322: Oil and Gas Lease | E322: 1677/533 | F322: 37361 | G322: 37389 | H322: David S. Silverberg | I322: EOG Resources, Inc. | J322: NW/4 SE/4, S/2 SE/4, SW/4 NE/4 of 31-12N-24W | L322: 36 | M322: 160 | O322: 38457 | Q322: 0.1875 | S322: F
A323: 209 | D323: Oil and Gas Lease | E323: 1677/535 | F323: 37361 | G323: 37389 | H323: Mary Ellen Silverberg | I323: EOG Resources Inc. | J323: NW/4 SE/4, S/2 SE/4, SW/4 NE/4 of 31-12N-24W
A324: 232 | D324: Oil and Gas Lease | E324: 1677/535 | F324: 37361 | G324: 37389 | H324: Mary Ellen Silverberg | I324: EOG Resources, Inc. | J324: NW/4 SE/4, S/2 SE/4, SW/4 NE/4 of 31-12N-24W
A325: 3 | D325: Lease | E325: 1677/512 | F325: 37384 | G325: 37389 | H325: Hayhurst Oil Properties Inc. | I325: Fleshman Agency Inc. | J325: 31-12N-24W | L325: 12 | M325: 180 | O325: 37749 | Q325: 0.25 | S325: F
A326: 4 | D326: Lease | E326: 1677/516 | F326: 37364 | G326: 37389 | H326: Lyle T. Ibeling | I326: Chesapeake Exploration Co. Ltd. Ptn | J326: 31-12N-24W | L326: 36 | M326: 160 | O326: 38460 | Q326: 0.25 | S326: F
A327: 5 | D327: Lease | E327: 1677/533 | F327: 37361 | G327: 37389 | H327: David S. Silverberg | I327: EOG Resources Inc. | J327: 31-12N-24W | L327: 36 | M327: 160 | O327: 38457 | Q327: 0.1875 | S327: F
A328: 212 | D328: Oil and Gas Lease | E328: 1678/554 | F328: 37381 | G328: 37399 | H328: Lyle T. Ibeling | I328: EOG Resources Inc. | J328: NW/4 SE/4, S/2 SE/4, SW/4 NE/4 of 31-12N-24W
A329: 234 | D329: Oil and Gas Lease | E329: 1678/554 | F329: 37381 | G329: 37399 | H329: Lyle T. Ibeling | I329: EOG Resources, Inc. | J329: NW/4 SE/4, S/2 SE/4, SW/4 NE/4 of 31-12N-24W
A330: 211 | D330: Oil and Gas Lease | E330: 1680/431 | F330: 37364 | G330: 37410 | H330: James E. Menchan | I330: Chesapeake Exploration Ltd. PTN | J330: E/2 SE/4, SW/4 NE/4 of 31-12N-24W
A331: 233 | D331: Oil and Gas Lease | E331: 1680/431 | F331: 37364 | G331: 37410 | H331: James E. Menchan | I331: Chesapeake Exploration, Ltd. Partnership | J331: E/2 SE/4, SW/4 NE/4 of 31-12N-24W
A332: 206 | D332: Oil and Gas Lease | E332: 1682/64 | F332: 37354 | G332: 37424 | H332: L. a. Persicke | I332: Chesapeake Exploration Ltd. PTN | J332: NW/4 SE/4, S/2 SE/4 of 31-12N-24W
A333: 231 | D333: Oil and Gas Lease | E333: 1682/64 | F333: 37354 | G333: 37424 | H333: L. A. Persicke | I333: Chesapeake Exploration, Ltd. Partnership | J333: NW/4 SE/4, S/2 SE/4 of 31-12N-24W
A334: 213 | D334: Oil and Gas Lease | E334: 1683/1 | F334: 37381 | G334: 37433 | H334: Deborah a. Deutsch, Paul R. Deutsch | I334: EOG Resources Inc. | J334: NW/4 SE/4, S/2 SE/4, SW/4 NE/4 of 31-12N-24W
A335: 6 | D335: Oil and Gas Lease | E335: 1683/1 | F335: 37381 | G335: 37433 | H335: Deborah A. Deutsch, Paul R. Deutsch | I335: EOG Resources, Inc. | J335: NW/4 SE/4, S/2 SE/4, SW/4 NE/4 of 31-12N-24W | L335: 36 | M335: 160 | O335: 38477 | Q335: 0.1875 | S335: F
A336: 6 | D336: Lease | E336: 1683/1 | F336: 37381 | G336: 37433 | H336: Paul R. & Deborah A. Deutseh | I336: EOG Resources | J336: 31-12N-24W | L336: 36 | M336: 160 | O336: 38477 | Q336: 0.1875 | S336: F
A337: 215 | D337: Oil and Gas Lease | E337: 1684/443 | F337: 37426 | G337: 37454 | H337: James F. Menehan | I337: EOG Resources Inc. | J337: NW/4 SE/4, S/2 SE/4, SW/4 NE/4 of 31-12N-24W
...

Sheet Runsheet
A1: Instrument # | B1: OGL | C1: Doc Type | D1: Bk/Pg. | E1: Effective Date | F1: Recorded Date | G1: Grantor | H1: Grantee | I1: Legal Description | J1: Notes | K1: Document Link
A2: 1905-000429 | C2: Deed | D2: D6/206 | E2: 2062 | F2: 2063 | G2: Leo Kennett | H2: Mack Hawbrook | I2: E/2 NW/4, Lots 1, 2 of 31-12N-24W | J2: ARTI | K2: =HYPERLINK("https://okcountyrecords.com/detail/roger+mills/1905-000429","OKCountyRecords: 1905-000429") -> OKCountyRecords: 1905-000429
A3: 1907-000709 | C3: Deed | D3: D9/303 | E3: 2592 | F3: 2601 | G3: Charles T. Kennett and Sadie N. Kennett, HW | H3: John G. Lancaster | I3: SW/4 NE/4 SW/4 SE/4, SE/4 SE/4 of 31-12N-24W | J3: ARTI | K3: =HYPERLINK("https://okcountyrecords.com/detail/roger+mills/1907-000709","OKCountyRecords: 1907-000709") -> OKCountyRecords: 1907-000709
A4: 1913-000413 | C4: Deed | D4: D19/268 | E4: 4759 | F4: 4759 | G4: Ernest Brooks and Mary Brooks, HW | H4: Susie Danforth, W. C. Danforth | I4: SE/4 NE/4, NE/4 SE/4 of 31-12N-24W | J4: ARTI | K4: =HYPERLINK("https://okcountyrecords.com/detail/roger+mills/1913-000413","OKCountyRecords: 1913-000413") -> OKCountyRecords: 1913-000413
A5: 1916-001105 | C5: Lease | D5: MIS9/513 | E5: 5913 | F5: 5913 | G5: W. D. Wilson | H5: Olo Olson | I5: All of 31-12N-24W aol | J5: Leasehold / WI | K5: =HYPERLINK("https://okcountyrecords.com/detail/roger+mills/1916-001105","OKCountyRecords: 1916-001105") -> OKCountyRecords: 1916-001105
A6: 1917-003351 | C6: Oil and Gas Lease | D6: OGL4/61 | E6: 6333 | F6: 6333 | G6: H. E. Rupp, L. M. Rupp | H6: Reo Oil & Gas Company | I6: 31-12N-24W, aol | J6: Leasehold / WI | K6: =HYPERLINK("https://okcountyrecords.com/detail/roger+mills/1917-003351","OKCountyRecords: 1917-003351") -> OKCountyRecords: 1917-003351
A7: 1917-003354 | C7: Oil and Gas Lease | D7: OGL4/64 | E7: 6333 | F7: 6333 | G7: M. Hambrook | H7: Reo Oil & Gas Company | I7: 31-12N-24W | J7: Leasehold / WI | K7: =HYPERLINK("https://okcountyrecords.com/detail/roger+mills/1917-003354","OKCountyRecords: 1917-003354") -> OKCountyRecords: 1917-003354
A8: 1917-003731 | C8: Oil and Gas Lease | D8: OGL5/320 | E8: 6399 | F8: 6399 | G8: Claude J. McGuire, Herbert E. McGuire | H8: Empire Gas & Fuel Company | I8: 31-12N-24W | J8: Leasehold / WI | K8: =HYPERLINK("https://okcountyrecords.com/detail/roger+mills/1917-003731","OKCountyRecords: 1917-003731") -> OKCountyRecords: 1917-003731
A9: 1917-003743 | C9: Oil and Gas Lease | D9: OGL5/332 | E9: 6399 | F9: 6399 | G9: C. S. Repass, Sarah Repass | H9: Empire Gas & Fuel Company | I9: 31-12N-24W | J9: Leasehold / WI | K9: =HYPERLINK("https://okcountyrecords.com/detail/roger+mills/1917-003743","OKCountyRecords: 1917-003743") -> OKCountyRecords: 1917-003743
A10: 1918-002463 | C10: Release | D10: REL9/108 | E10: 6589 | F10: 6589 | G10: State Life Ins Co | H10: Claude J. McGuire, Herbert E. McGuire | I10: 31-12N-24W | J10: Leasehold / WI | K10: =HYPERLINK("https://okcountyrecords.com/detail/roger+mills/1918-002463","OKCountyRecords: 1918-002463") -> OKCountyRecords: 1918-002463
A11: 1918-002091 | C11: Release | D11: REL5/251 | E11: 6596 | F11: 6596 | G11: E. C. Thorne | H11: Claude McGuire, Herbert E. McGuire | I11: 31-12N-24W | J11: Leasehold / WI | K11: =HYPERLINK("https://okcountyrecords.com/detail/roger+mills/1918-002091","OKCountyRecords: 1918-002091") -> OKCountyRecords: 1918-002091
A12: 1919-002106 | C12: Oil and Gas Lease | D12: OGL4/401 | E12: 7090 | F12: 7090 | G12: Susie Danforth, W. C. Danforth | H12: John R. Williams | I12: 31-12N-24W | J12: Leasehold / WI | K12: =HYPERLINK("https://okcountyrecords.com/detail/roger+mills/1919-002106","OKCountyRecords: 1919-002106") -> OKCountyRecords: 1919-002106
A13: 1920-000012 | C13: Assignment | D13: ASN4/82 | E13: 7317 | F13: 7317 | G13: Martin Loan & Investment Company | H13: Florence Lewis | I13: 31-12N-24W | J13: Leasehold / WI | K13: =HYPERLINK("https://okcountyrecords.com/detail/roger+mills/1920-000012","OKCountyRecords: 1920-000012") -> OKCountyRecords: 1920-000012
A14: 1920-002046 | C14: Oil and Gas Lease | D14: OGL4/556 | E14: 7341 | F14: 7341 | G14: Margaret V. Black, William G. Black | H14: W. E. Thomas | I14: 31-12N-24W, aol | J14: Leasehold / WI | K14: =HYPERLINK("https://okcountyrecords.com/detail/roger+mills/1920-002046","OKCountyRecords: 1920-002046") -> OKCountyRecords: 1920-002046
A15: 1921-001533 | C15: Release | D15: REL11/342 | E15: 7682 | F15: 7682 | G15: H. L. Rowley | H15: H. E. Rupp, Lula M. Rupp | I15: 31-12N-24W, aol | J15: Leasehold / WI | K15: =HYPERLINK("https://okcountyrecords.com/detail/roger+mills/1921-001533","OKCountyRecords: 1921-001533") -> OKCountyRecords: 1921-001533
A16: 1923-002282 | C16: Oil and Gas Lease | D16: OGL6/484 | E16: 8513 | F16: 8513 | G16: E. T. Gamble, Zella Gamble | H16: Calvin M. Rosser | I16: 31-12N-24W | J16: Leasehold / WI | K16: =HYPERLINK("https://okcountyrecords.com/detail/roger+mills/1923-002282","OKCountyRecords: 1923-002282") -> OKCountyRecords: 1923-002282
A17: 1925-000406 | C17: Deed | D17: D34/104 | E17: 9137 | F17: 9137 | G17: E. T. Gamble and Zella M. Gamble, HW | H17: Leo Aulbert | I17: S/2 SW/4, S/2 N/2 SW/4 of 31-12N-24W | J17: ARTI | K17: =HYPERLINK("https://okcountyrecords.com/detail/roger+mills/1925-000406","OKCountyRecords: 1925-000406") -> OKCountyRecords: 1925-000406
A18: 1928-002014 | C18: Release | D18: REL15/588 | E18: 10238 | F18: 10238 | G18: E. C. Thorne | H18: Claude J. McGuire, Herbert E. McGuire | I18: 31-12N-24W | J18: Leasehold / WI | K18: =HYPERLINK("https://okcountyrecords.com/detail/roger+mills/1928-002014","OKCountyRecords: 1928-002014") -> OKCountyRecords: 1928-002014
A19: 1930-003190 | C19: Release | D19: REL16/331 | E19: 10964 | F19: 10964 | G19: Albert G. Frick | H19: H. E. Rupp, Lula Rupp | I19: 31-12N-24W, aol | J19: Leasehold / WI | K19: =HYPERLINK("https://okcountyrecords.com/detail/roger+mills/1930-003190","OKCountyRecords: 1930-003190") -> OKCountyRecords: 1930-003190
A20: 1930-002708 | C20: Oil and Gas Lease | D20: OGL8/649 | E20: 11164 | F20: 11164 | G20: Louis E. Jaques, Virginia Jaques | H20: Roy M. Johnson | I20: 31-12N-24W, aol | J20: Leasehold / WI | K20: =HYPERLINK("https://okcountyrecords.com/detail/roger+mills/1930-002708","OKCountyRecords: 1930-002708") -> OKCountyRecords: 1930-002708
A21: 1931-001768 | C21: Oil and Gas Lease | D21: OGL9/176 | E21: 11364 | F21: 11364 | G21: Swinburn J. Stewart | H21: Roy M. Johnson | I21: 31-12N-24W | J21: Leasehold / WI | K21: =HYPERLINK("https://okcountyrecords.com/detail/roger+mills/1931-001768","OKCountyRecords: 1931-001768") -> OKCountyRecords: 1931-001768
A22: 2005-008386 | C22: Order and Final Decree | D22: 1816/41 | E22: 12655 | F22: 38695 | G22: Roger Mills County Court RE: In the Matter of the Estate of Louis E. Jaques, deceased | H22: Virginia Jaques, widow, 1/2, Ethel Brister, 1/2 | I22: N/2 NE/4 of 31-12N-24W, aol | J22: ARTI | K22: =HYPERLINK("https://okcountyrecords.com/detail/roger+mills/2005-008386","OKCountyRecords: 2005-008386") -> OKCountyRecords: 2005-008386
A23: 1937-000416 | C23: Warranty Deed | D23: D48/72 | E23: 13545 | F23: 13545 | G23: Virginia Jaques and N. Virgina Jacques, one and the same person, a widow | H23: H. M. Carter | I23: N/2 NE/4 of 31-12N-24W, aol | J23: ARTI Subject to 1/2 of the royalty sold to Panhandle Co-Operative Royalty Company | K23: =HYPERLINK("https://okcountyrecords.com/detail/roger+mills/1937-000416","OKCountyRecords: 1937-000416") -> OKCountyRecords: 1937-000416
A24: 1945-000816 | C24: Final Decree | D24: MIS22/628 | E24: 16439 | F24: 16439 | G24: Beckham County Court, RE: In the Matter of the Estate of Benjamin H. Shotwell, Deceased | H24: Maggie Bennett, Eli L. Shotwell, Pearl L. Davis, Roy T. Shotwell, Ida M. Cuff | I24: SE/4 NE/4, NE/4 SE/4 of 31-12N-24W, aol | J24: ARTI | K24: =HYPERLINK("https://okcountyrecords.com/detail/roger+mills/1945-000816","OKCountyRecords: 1945-000816") -> OKCountyRecords: 1945-000816
A25: 1946-001487 | C25: Oil and Gas Lease | D25: OGL11/83 | E25: 16860 | F25: 16860 | G25: Lee Aulbert, Mollie Aulbert | H25: Tom R. Johnson Jr. | I25: 31-12N-24W | J25: Leasehold / WI | K25: =HYPERLINK("https://okcountyrecords.com/detail/roger+mills/1946-001487","OKCountyRecords: 1946-001487") -> OKCountyRecords: 1946-001487
A26: 1946-001492 | C26: Oil and Gas Lease | D26: OGL11/88 | E26: 16860 | F26: 16860 | G26: Eula Bain, William C. Bain | H26: O. C. Robinson | I26: 31-12N-24W | J26: Leasehold / WI | K26: =HYPERLINK("https://okcountyrecords.com/detail/roger+mills/1946-001492","OKCountyRecords: 1946-001492") -> OKCountyRecords: 1946-001492
A27: 1948-002010 | C27: Oil and Gas Lease | D27: OGL11/337 | E27: 17549 | F27: 17549 | G27: J. E. Campbell, Lillie A. Campbell | H27: C. L. Moss | I27: 31-12N-24W | J27: Leasehold / WI | K27: =HYPERLINK("https://okcountyrecords.com/detail/roger+mills/1948-002010","OKCountyRecords: 1948-002010") -> OKCountyRecords: 1948-002010
A28: 1948-000087 | C28: Assignment | D28: ASN14/269 | E28: 17554 | F28: 17554 | G28: J. B. Campbell, Lillie A. Campbell, Lillie A. Hambrook | H28: Commissioners of the Land Office | I28: 31-12N-24W | J28: Leasehold / WI | K28: =HYPERLINK("https://okcountyrecords.com/detail/roger+mills/1948-000087","OKCountyRecords: 1948-000087") -> OKCountyRecords: 1948-000087
A29: 1949-001867 | C29: Mineral Deed | D29: D63/97 | E29: 18170 | F29: 18170 | G29: H. M. Carter and Ethel Carter, HW | H29: G. C. Mitchel, Glenn D. Mitchel | I29: E/2 NW/4, SE/4 NE/4, NE/4 SE/4, N/2 NE/4 SW/4 of 31-12N-24W, aol | J29: 20/260 interest, being 20 NMA in 2 sections | K29: =HYPERLINK("https://okcountyrecords.com/detail/roger+mills/1949-001867","OKCountyRecords: 1949-001867") -> OKCountyRecords: 1949-001867
A30: 1950-000383 | C30: Warranty Deed | D30: D59/410 | E30: 18420 | F30: 18420 | G30: H. M. Carter and Ethel Carter, HW | H30: Marvin G. Mitchell and Carrie Lou Mitchell, HW, JTWROS | I30: E/2 NW/4, SE/4 NE/4, NE/4 SE/4, N/2 NE/4 SW/4 of 31-12N-24W, aol | J30: ARTI, Except 1/2 of the ogms in the N/2 NE/4 Corrects deed dated 2/21/1949 | K30: =HYPERLINK("https://okcountyrecords.com/detail/roger+mills/1950-000383","OKCountyRecords: 1950-000383") -> OKCountyRecords: 1950-000383
A31: 1951-001020 | C31: Surface Warranty Deed | D31: D65/63 | E31: 18680 | F31: 18680 | G31: Marvin G. Mitchell and Carrie Lou Mitchell, HW | H31: Elvin J. Ridling | I31: E/2 NW/4, SE/4 NE/4, NE/4 SE/4, N/2 NE/4 SW/4 of 31-12N-24W, aol | J31: Surface only, Grantors reserve all minerals | K31: =HYPERLINK("https://okcountyrecords.com/detail/roger+mills/1951-001020","OKCountyRecords: 1951-001020") -> OKCountyRecords: 1951-001020
A32: 1953-000493 | C32: Warranty Deed | D32: D67/154 | E32: 19396 | F32: 19396 | G32: Elvin J. Ridling and Dorothy Jean Ridling, HW | H32: M. G. Mitchell and Carrie Lou Mitchell, HW, JTWROS | I32: E/2 NW/4, SE/4 NE/4, NE/4 SE/4, N/2 NE/4 SW/4, Lot 4, S/2 SW/4, SE/4 SW/4 of 31-12N-24W | J32: ARTI | K32: =HYPERLINK("https://okcountyrecords.com/detail/roger+mills/1953-000493","OKCountyRecords: 1953-000493") -> OKCountyRecords: 1953-000493
A33: 1962-000500 | C33: Oil and Gas Lease | D33: MIS45/202 | E33: 22761 | F33: 22761 | G33: Joseph Devenas, Mary Margaret Devenas | H33: Robert O. Lister Jr. | I33: All of 31-12N-24W aol | J33: Leasehold / WI | K33: =HYPERLINK("https://okcountyrecords.com/detail/roger+mills/1962-000500","OKCountyRecords: 1962-000500") -> OKCountyRecords: 1962-000500
A34: 1962-000501 | C34: Oil and Gas Lease | D34: MIS45/204 | E34: 22761 | F34: 22761 | G34: Margaret Gray, Murrell Gray | H34: Robert O. Lister Jr. | I34: All of 31-12N-24W aol | J34: Leasehold / WI | K34: =HYPERLINK("https://okcountyrecords.com/detail/roger+mills/1962-000501","OKCountyRecords: 1962-000501") -> OKCountyRecords: 1962-000501
A35: 1962-000502 | C35: Oil and Gas Lease | D35: MIS45/206 | E35: 22761 | F35: 22761 | G35: Gladys Priest | H35: Robert O. Lister Jr. | I35: All of 31-12N-24W aol | J35: Leasehold / WI | K35: =HYPERLINK("https://okcountyrecords.com/detail/roger+mills/1962-000502","OKCountyRecords: 1962-000502") -> OKCountyRecords: 1962-000502
A36: 1962-000503 | C36: Oil and Gas Lease | D36: MIS45/208 | E36: 22761 | F36: 22761 | G36: Ethel I. Carter, H. M. Carter | H36: Robert O. Lister Jr. | I36: All of 31-12N-24W aol | J36: Leasehold / WI | K36: =HYPERLINK("https://okcountyrecords.com/detail/roger+mills/1962-000503","OKCountyRecords: 1962-000503") -> OKCountyRecords: 1962-000503
A37: 1962-000505 | C37: Oil and Gas Lease | D37: MIS45/212 | E37: 22761 | F37: 22761 | G37: Carrie Lou Mitchell, Marvin G. Mitchell | H37: Robert O. Lister Jr. | I37: All of 31-12N-24W | J37: Leasehold / WI | K37: =HYPERLINK("https://okcountyrecords.com/detail/roger+mills/1962-000505","OKCountyRecords: 1962-000505") -> OKCountyRecords: 1962-000505
A38: 1962-000506 | C38: Oil and Gas Lease | D38: MIS45/214 | E38: 22761 | F38: 22761 | G38: Carrie Lou Mitchell, Marvin G. Mitchell | H38: Robert O. Lister Jr. | I38: All of 31-12N-24W | J38: Leasehold / WI | K38: =HYPERLINK("https://okcountyrecords.com/detail/roger+mills/1962-000506","OKCountyRecords: 1962-000506") -> OKCountyRecords: 1962-000506
A39: 1962-000726 | C39: Oil and Gas Lease | D39: MIS45/598 | E39: 22816 | F39: 22816 | G39: Carrie Lou Mitchell, Marvin G. Mitchell | H39: Robert O. Lister Jr. | I39: All of 31-12N-24W | J39: Leasehold / WI | K39: =HYPERLINK("https://okcountyrecords.com/detail/roger+mills/1962-000726","OKCountyRecords: 1962-000726") -> OKCountyRecords: 1962-000726
A40: 1962-000727 | C40: Oil and Gas Lease | D40: MIS45/600 | E40: 22816 | F40: 22816 | G40: Carrie Lou Mitchell, Marvin G. Mitchell | H40: Robert O. Lister Jr. | I40: All of 31-12N-24W | J40: Leasehold / WI | K40: =HYPERLINK("https://okcountyrecords.com/detail/roger+mills/1962-000727","OKCountyRecords: 1962-000727") -> OKCountyRecords: 1962-000727
...

Sheet Tract 1
E1: Instrument | H1: Patent | I1: Deed | J1: Mineral Deed | K1: Mineral Deed | L1: Warranty Deed | M1: Mineral Deed | N1: Mineral Deed | O1: Quit Claim Deed | P1: Mineral Deed | Q1: Mineral Deed | R1: Decree | S1: Mineral Deed | T1: Warranty Deed | U1: Final Decree | V1: Mineral Deed | W1: Mineral Deed | X1: Mineral Deed | Y1: Final Decree | Z1: Quit Claim Deed | AA1: Joint Tenancy Warranty Deed | AB1: Trustees Mineral Deed | AC1: Trustees Mineral Deed | AD1: Trustees Mineral Deed | AE1: Final Decree | AF1: Mineral Deed | AG1: Mineral Deed | AH1: Quit Claim Mineral Deed | AI1: Mineral Deed | AJ1: Quit Claim Mineral Deed | AK1: Mineral Deed
A2: 1 | B2: TRACT | D2: N/2 NE/4, containing 80 acres | E2: Image Number | H2: 1930-002914 | I2: 1988-004185 | J2: 1994-006415 | K2: 1995-003404 | L2: 1996-002352 | M2: 2000-007685 | N2: 2001-000957 | O2: 2001-001092 | P2: 2001-001414 | Q2: 2001-001463 | R2: 2001-002342 | S2: 2002-004595 | T2: 2003-004945 | U2: 2004-000099 | V2: 2004-005901 | W2: 2005-000158 | X2: 2005-007551 | Y2: 2005-008386 | Z2: 2007-001848 | AA2: 2008-003157 | AB2: 2011-001007 | AC2: 2011-001008 | AD2: 2011-001009 | AE2: 2013-000518 | AF2: 2014-003089 | AG2: 2014-006293 | AH2: 2016-001882 | AJ2: 2018-002650 | AK2: 2021-001068
B3: DESCRIPTION | E3: Book / Page | H3: PAT010/234 | I3: 0981/0002 | J3: 1422/0009 | K3: 1457/0173 | L3: 1510/0491 | M3: 1611/0503 | N3: 1637/0026 | O3: 1637/0476 | P3: 1639/0206 | Q3: 1639/0426 | R3: 1643/0389 | S3: 1695/0238 | T3: 1724/0582 | U3: 1734/0014 | V3: 1765/0306 | W3: 1774/0309 | X3: 1812/0138 | Y3: 1816/0041 | Z3: 1872/0277 | AA3: 1914/0155 | AB3: 2063/0491 | AC3: 2063/0494 | AD3: 2063/0497 | AE3: 2177/0033 | AF3: 2251/0529 | AG3: 2273/0223 | AH3: 2342/0219 | AI3: 2376/0100 | AJ3: 2406/0228 | AK3: 2467/0476
E4: Date | H4: 11021 | I4: 32329 | J4: 34542 | K4: 34754 | L4: 35429 | M4: 36647 | N4: 36957 | O4: 36969 | P4: 36987 | Q4: 36991 | R4: 37034 | S4: 37592 | T4: 37897 | U4: 37994 | V4: 38281 | W4: 38365 | X4: 38658 | Y4: 38695 | Z4: 39197 | AA4: 39612 | AB4: 40592 | AC4: 40592 | AD4: 40592 | AE4: 41304 | AF4: 41774 | AG4: 41927 | AH4: 42593 | AI4: 42996 | AJ4: 43382 | AK4: 44377
B5: TRACT ACRES | D5: 80 | E5: Conveyance | H5: ARTI | I5: ARTI | J5: ARTI | K5: ARTI | L5: ARTI | M5: ARTI | N5: ARTI | O5: ARTI | P5: ARTI | Q5: ARTI | R5: ARTI | S5: ARTI | T5: ARTI | U5: ARTI | V5: ARTI | W5: ARTI | X5: ARTI | Y5: ARTI | Z5: ARTI | AA5: ARTI | AB5: ARTI | AC5: ARTI | AD5: ARTI | AE5: ARTI | AF5: ARTI | AG5: ARTI | AH5: ARTI | AI5: ARTI | AJ5: ARTI | AK5: ARTI
B6: BASE OGL | C6: 80 | D6: Tract 1 | E6: =SUBTOTAL(9,E9:E205) -> 0 | F6: SURFACE | H6: =IF(H7=0,"","RECHECK") | I6: =IF(I7=0,"","RECHECK") | J6: =IF(J7=0,"","RECHECK") | L6: =IF(L7=0,"","RECHECK") | M6: =IF(M7=0,"","RECHECK") | N6: =IF(N7=0,"","RECHECK") | O6: =IF(O7=0,"","RECHECK") | P6: =IF(P7=0,"","RECHECK") | Q6: =IF(Q7=0,"","RECHECK") | R6: =IF(R7=0,"","RECHECK") | S6: =IF(S7=0,"","RECHECK") | ... AF6: =IF(AF7=0,"","RECHECK") | AJ6: =IF(AJ7=0,"","RECHECK") | AK6: =IF(AK7=0,"","RECHECK") | AL6: =IF(AL7=0,"","RECHECK") | AM6: =IF(AM7=0,"","RECHECK") | AP6: =IF(AP7=0,"","RECHECK") | AQ6: =IF(AQ7=0,"","RECHECK") | AR6: =IF(AR7=0,"","RECHECK") | AS6: =IF(AS7=0,"","RECHECK") | AT6: =IF(AT7=0,"","RECHECK") | AU6: =IF(AU7=0,"","RECHECK") | AV6: =IF(AV7=0,"","RECHECK") | AW6: =IF(AW7=0,"","RECHECK") | ... FX6: =IF(FX7=0,"","RECHECK")
G7: =SUBTOTAL(9,G10:G206) -> 0 | H7: =SUBTOTAL(9,H10:H206) -> 0 | I7: =SUBTOTAL(9,I10:I206) -> 0 | J7: =SUBTOTAL(9,J10:J206) -> 0 | K7: =SUBTOTAL(9,K10:K206) -> 0 | L7: =SUBTOTAL(9,L10:L206) -> 0 | M7: =SUBTOTAL(9,M10:M206) -> 0 | N7: =SUBTOTAL(9,N10:N206) -> 0 | ... AJ7: =SUBTOTAL(9,AJ10:AJ206) -> 0 | AK7: 0 | AL7: =SUBTOTAL(9,AL10:AL206) -> 0 | AM7: =SUBTOTAL(9,AM10:AM206) -> 0 | AN7: =SUBTOTAL(9,AN10:AN201) -> 0 | AO7: =SUBTOTAL(9,AO10:AO195) -> 0 | AP7: =SUBTOTAL(9,AP10:AP195) -> 0 | AQ7: =SUBTOTAL(9,AQ10:AQ195) -> 0 | AR7: =SUBTOTAL(9,AR10:AR195) -> 0 | AS7: =SUBTOTAL(9,AS10:AS206) -> 0 | AT7: =SUBTOTAL(9,AT10:AT206) -> 0 | AU7: =SUBTOTAL(9,AU10:AU206) -> 0 | AV7: =SUBTOTAL(9,AV10:AV202) -> 0 | AW7: =SUBTOTAL(9,AW10:AW206) -> 0 | AX7: =SUBTOTAL(9,AX10:AX206) -> 0 | AY7: =SUBTOTAL(9,AY10:AY206) -> 0 | AZ7: =SUBTOTAL(9,AZ10:AZ206) -> 0 | BA7: =SUBTOTAL(9,BA10:BA206) -> 0 | BB7: =SUBTOTAL(9,BB10:BB206) -> 0 | BC7: =SUBTOTAL(9,BC10:BC206) -> 0 | BD7: =SUBTOTAL(9,BD10:BD206) -> 0 | ... FX7: =SUBTOTAL(9,FX10:FX206) -> 0
A8: NOTES | C8: NET ACRES | D8: OWNERS | E8: TOTAL
C10: =IFERROR(IF($E10>0,$E10/SUMIF($E$10:$E$75,">0")*$D$5,""),"") | D10: United States of America | E10: =SUM(G10:HQ10) -> -1 | H10: -1
C11: =IFERROR(IF($E11>0,$E11/SUMIF($E$10:$E$75,">0")*$D$5,""),"") -> 4.7058824 | D11: Roy A. Garrison | E11: =SUM(G11:HQ11) -> 1 | H11: 1
C12: =IFERROR(IF($E12>0,$E12/SUMIF($E$10:$E$75,">0")*$D$5,""),"") | D12: Flag-redfern Oil Company | E12: =SUM(G12:HQ12) -> 0
C13: =IFERROR(IF($E13>0,$E13/SUMIF($E$10:$E$75,">0")*$D$5,""),"") | D13: Eta-flag Royalty Trust | E13: =SUM(G13:HQ13) -> -1 | J13: -1
C14: =IFERROR(IF($E14>0,$E14/SUMIF($E$10:$E$75,">0")*$D$5,""),"") -> 4.7058824 | D14: First City National Bank of Midland Trustee | E14: =SUM(G14:HQ14) -> 1 | J14: 1
C15: =IFERROR(IF($E15>0,$E15/SUMIF($E$10:$E$75,">0")*$D$5,""),"") | D15: Hayhurst Oil Properties, Inc. | E15: =SUM(G15:HQ15) -> -1 | J15: -1
C16: =IFERROR(IF($E16>0,$E16/SUMIF($E$10:$E$75,">0")*$D$5,""),"") -> 4.7058824 | D16: Nam Corporation | E16: =SUM(G16:HQ16) -> 1 | J16: 1
C17: =IFERROR(IF($E17>0,$E17/SUMIF($E$10:$E$75,">0")*$D$5,""),"") | D17: Tripco, Inc. | E17: =SUM(G17:HQ17) -> -2 | K17: -1 | X17: -1
C18: =IFERROR(IF($E18>0,$E18/SUMIF($E$10:$E$75,">0")*$D$5,""),"") -> 4.7058824 | D18: Prudential Securities | E18: =SUM(G18:HQ18) -> 1 | K18: 1
C19: =IFERROR(IF($E19>0,$E19/SUMIF($E$10:$E$75,">0")*$D$5,""),"") | D19: Eula Cross | E19: =SUM(G19:HQ19) -> 0
C20: =IFERROR(IF($E20>0,$E20/SUMIF($E$10:$E$75,">0")*$D$5,""),"") | D20: Floyd W. Atha | E20: =SUM(G20:HQ20) -> 0
C21: =IFERROR(IF($E21>0,$E21/SUMIF($E$10:$E$75,">0")*$D$5,""),"") | D21: Nancy D. Atha | E21: =SUM(G21:HQ21) -> 0
C22: =IFERROR(IF($E22>0,$E22/SUMIF($E$10:$E$75,">0")*$D$5,""),"") | D22: Fer-scher Exploration, LLC | E22: =SUM(G22:HQ22) -> -1 | M22: -1
C23: =IFERROR(IF($E23>0,$E23/SUMIF($E$10:$E$75,">0")*$D$5,""),"") -> 4.7058824 | D23: Aspen Minerals Group | E23: =SUM(G23:HQ23) -> 1 | M23: 1
C24: =IFERROR(IF($E24>0,$E24/SUMIF($E$10:$E$75,">0")*$D$5,""),"") | D24: Nanalee Faye Barnett | E24: =SUM(G24:HQ24) -> -1 | N24: -1
C25: =IFERROR(IF($E25>0,$E25/SUMIF($E$10:$E$75,">0")*$D$5,""),"") -> 14.117647 | D25: Arrowhead Resources, Inc. | E25: =SUM(G25:HQ25) -> 3 | N25: 1 | P25: 1 | Q25: 1
C26: =IFERROR(IF($E26>0,$E26/SUMIF($E$10:$E$75,">0")*$D$5,""),"") | D26: Laurence L. Crouse, Trustee | E26: =SUM(G26:HQ26) -> -1 | O26: -1
C27: =IFERROR(IF($E27>0,$E27/SUMIF($E$10:$E$75,">0")*$D$5,""),"") -> 4.7058824 | D27: Crouse Family Limited Partnerhsip | E27: =SUM(G27:HQ27) -> 1 | O27: 1
C28: =IFERROR(IF($E28>0,$E28/SUMIF($E$10:$E$75,">0")*$D$5,""),"") | D28: Louise Ormand | E28: =SUM(G28:HQ28) -> -1 | P28: -1
C29: =IFERROR(IF($E29>0,$E29/SUMIF($E$10:$E$75,">0")*$D$5,""),"") | D29: Glenn D. Mitchel | E29: =SUM(G29:HQ29) -> -1 | Q29: -1
C30: =IFERROR(IF($E30>0,$E30/SUMIF($E$10:$E$75,">0")*$D$5,""),"") | D30: Jack E. Barnett, Deceased | E30: =SUM(G30:HQ30) -> -1 | R30: -1
C31: =IFERROR(IF($E31>0,$E31/SUMIF($E$10:$E$75,">0")*$D$5,""),"") -> 14.117647 | D31: The Public | E31: =SUM(G31:HQ31) -> 3 | R31: 1 | U31: 1 | Y31: 1
C32: =IFERROR(IF($E32>0,$E32/SUMIF($E$10:$E$75,">0")*$D$5,""),"") | D32: Hayhurst, Peggy J. Revoc Trust | E32: =SUM(G32:HQ32) -> 0
C33: =IFERROR(IF($E33>0,$E33/SUMIF($E$10:$E$75,">0")*$D$5,""),"") | D33: Peggy J. | E33: =SUM(G33:HQ33) -> 0
C34: =IFERROR(IF($E34>0,$E34/SUMIF($E$10:$E$75,">0")*$D$5,""),"") | D34: Bluebonnet Investments, Ltd. | E34: =SUM(G34:HQ34) -> -1 | T34: -1
C35: =IFERROR(IF($E35>0,$E35/SUMIF($E$10:$E$75,">0")*$D$5,""),"") -> 4.7058824 | D35: White Birch, LP | E35: =SUM(G35:HQ35) -> 1 | T35: 1
C36: =IFERROR(IF($E36>0,$E36/SUMIF($E$10:$E$75,">0")*$D$5,""),"") | D36: Evelyn Louise McLerran, Deceased | E36: =SUM(G36:HQ36) -> -1 | U36: -1
C37: =IFERROR(IF($E37>0,$E37/SUMIF($E$10:$E$75,">0")*$D$5,""),"") | D37: Aspen Energy Group, Inc. | E37: =SUM(G37:HQ37) -> -1 | V37: -1
C38: =IFERROR(IF($E38>0,$E38/SUMIF($E$10:$E$75,">0")*$D$5,""),"") -> 4.7058824 | D38: Crusader Energy Corporation | E38: =SUM(G38:HQ38) -> 1 | V38: 1
C39: =IFERROR(IF($E39>0,$E39/SUMIF($E$10:$E$75,">0")*$D$5,""),"") | D39: Minion Investment Co | E39: =SUM(G39:HQ39) -> 0
C40: =IFERROR(IF($E40>0,$E40/SUMIF($E$10:$E$75,">0")*$D$5,""),"") | D40: Brian L. Rice | E40: =SUM(G40:HQ40) -> 0
C41: =IFERROR(IF($E41>0,$E41/SUMIF($E$10:$E$75,">0")*$D$5,""),"") -> 4.7058824 | D41: Prism Energy, Inc. | E41: =SUM(G41:HQ41) -> 1 | X41: 1
...

Sheet Tract 2
E1: Instrument | H1: Patent | I1: Quit Claim Deed | J1: Mineral Deed | K1: Final Decree | L1: Quit Claim Mineral Deed | M1: Quit Claim Mineral Deed | N1: Mineral Deed | O1: Mineral Deed | P1: Mineral Deed | Q1: Mineral Deed | R1: Mineral Deed | S1: Mineral Deed | T1: Mineral Deed | U1: Mineral Deed | V1: Mineral Deed | W1: Quit Claim Mineral Deed | X1: Mineral Deed | Y1: Mineral Deed | Z1: Mineral Deed | AA1: Mineral Deed | AB1: Mineral Deed | AC1: Quit Claim Deed | AD1: Deed | AE1: Mineral Deed | AF1: Mineral Deed | AG1: Mineral Deed | AH1: Mineral Deed | AI1: Mineral Deed | AJ1: Mineral Deed | AK1: Mineral Deed | AL1: Mineral Deed | AM1: Mineral Deed | AN1: Mineral Deed | AO1: Final Decree | AP1: Mineral Deed | AQ1: Mineral Deed | AR1: Quit Claim Mineral Deed | AS1: Mineral Deed | AT1: Mineral Deed | AU1: Mineral Deed | AV1: Mineral Deed | AW1: Deed | AX1: Mineral Deed | AY1: Mineral Deed | AZ1: Mineral Deed | BA1: Mineral Deed | BB1: Final Decree | BC1: Mineral Deed | BD1: Mineral Deed | BE1: Mineral Deed | BF1: Mineral Deed | BG1: Mineral Deed | BH1: Quit Claim Mineral Deed | BI1: Mineral Deed | BJ1: Mineral Deed | BK1: Mineral Deed | BL1: Mineral Deed | BM1: Mineral Deed | BN1: Mineral Deed | BO1: Final Decree
A2: 2 | B2: TRACT | D2: SW/4 SE/4, containing 40 acres | E2: Image Number | I2: 1995-004151 | J2: 1995-000396 | K2: 1995-001954 | L2: 1998-000584 | M2: 1998-000907 | N2: 1999-002219 | O2: 1999-002220 | P2: 1999-002739 | Q2: 1999-003363 | R2: 1999-003368 | S2: 1999-003364 | T2: 1999-003365 | U2: 1999-003366 | V2: 1999-003367 | W2: 2000-010180 | X2: 2001-000103 | Y2: 2001-000921 | Z2: 2001-000926 | AA2: 2001-000927 | AB2: 2002-004378 | AC2: 2003-003131 | AD2: 2005-000347 | AE2: 2005-001909 | AF2: 2005-003389 | AG2: 2005-007117 | AH2: 2005-007116 | AI2: 2005-007119 | AJ2: 2005-007120 | AK2: 2005-007540 | AL2: 2005-007541 | AM2: 2006-003765 | AN2: 2007-001374 | AO2: 2007-005167 | AP2: 2008-007325 | AQ2: 2009-000895 | AR2: 2010-002337 | AS2: 2010-005993 | AT2: 2010-007125 | AU2: 2010-008922 | AV2: 2011-003023 | AW2: 2011-007728 | AX2: 2011-007729 | AY2: 2012-002930 | AZ2: 2013-006083 | BA2: 2014-002935 | BB2: 2014-004286 | BC2: 2015-000877 | BD2: 2015-002791 | BE2: 2015-003284 | BG2: 2019-001747 | BH2: 2020-001650 | BI2: 2021-001774 | BJ2: 2023-002269 | BK2: 2025-002464 | BL2: 2025-002463 | BM2: 2025-005448 | BN2: 2025-005451 | BO2: 2026-003315
B3: DESCRIPTION | E3: Book / Page | H3: PAT006/74 | I3: 1462/0131 | J3: 1470/0059 | K3: 1479/0191 | L3: 1564/0310 | M3: 1567/0245 | N3: 1576/0219 | O3: 1576/0222 | P3: 1579/0358 | Q3: 1583/0391 | R3: 1583/0426 | S3: 1583/0398 | T3: 1583/0405 | U3: 1583/0412 | V3: 1583/0419 | W3: 1625/0440 | X3: 1631/0416 | Y3: 1636/0544 | Z3: 1636/0554 | AA3: 1636/0556 | AB3: 1694/0156 | AC3: 1714/0504 | AD3: 1775/0296 | AE3: 1783/0306 | AF3: 1790/0386 | AG3: 1810/0016 | AH3: 1810/0015 | AI3: 1810/0018 | AJ3: 1810/0019 | AK3: 1812/0120 | AL3: 1812/0121 | AM3: 1838/0136 | AN3: 1869/0351 | AO3: 1892/0567 | AP3: 1941/0550 | AQ3: 1949/0217 | AR3: 2002/0576 | AS3: 2022/0493 | AT3: 2031/0005 | AU3: 2041/0379 | AV3: 2074/0536 | AW3: 2104/0239 | AX3: 2104/0242 | AY3: 2131/0599 | AZ3: 2219/0516 | BA3: 2251/0022 | BB3: 2259/0397 | BC3: 2290/0178 | BD3: 2309/0236 | BE3: 2315/0042 | BF3: 2376/0100 | BG3: 2425/0225 | BH3: 2453/0219 | BI3: 2481/0287 | BJ3: 2529/0217 | BK3: 2625/0233 | BL3: 2625/0231 | BM3: 2649/0286 | BN3: 2649/0298 | BO3: 2704/0142
E4: Date | I4: 34806 | J4: 34920 | K4: 35038 | L4: 36026 | M4: 36059 | N4: 36175 | O4: 36175 | P4: 36215 | Q4: 36270 | R4: 36270 | S4: 36270 | T4: 36270 | U4: 36270 | V4: 36270 | W4: 36815 | X4: 36899 | Y4: 36956 | Z4: 36956 | AA4: 36956 | AB4: 37573 | AC4: 37797 | AD4: 38376 | AE4: 38446 | AF4: 38490 | AG4: 38642 | AH4: 38642 | AI4: 38642 | AJ4: 38642 | AK4: 38658 | AL4: 38658 | AM4: 38856 | AN4: 39167 | AO4: 39400 | AP4: 39783 | AQ4: 39874 | AR4: 40238 | AS4: 40336 | AT4: 40374 | AU4: 40438 | AV4: 40665 | AW4: 40869 | AX4: 40869 | AY4: 41015 | AZ4: 41592 | BA4: 41766 | BB4: 41821 | BC4: 42068 | BD4: 42255 | BE4: 42313 | BF4: 42996 | BG4: 43693 | BH4: 44133 | BI4: 44491 | BJ4: 45114 | BK4: 45771 | BL4: 45771 | BM4: 45908 | BN4: 45908 | BO4: 46178
B5: TRACT ACRES | D5: 40 | E5: Conveyance | H5: ARTI | I5: ARTI | J5: ARTI | K5: ARTI | L5: ARTI | M5: ARTI | N5: ARTI | O5: ARTI | P5: ARTI | Q5: ARTI | R5: ARTI | S5: ARTI | T5: ARTI | U5: ARTI | V5: ARTI | W5: ARTI | X5: ARTI | Y5: ARTI | Z5: ARTI | AA5: ARTI | AB5: ARTI | AC5: ARTI | AD5: ARTI | AE5: ARTI | AF5: ARTI | AG5: ARTI | AH5: ARTI | AI5: ARTI | AJ5: ARTI | AK5: ARTI | AL5: ARTI | AM5: ARTI | AN5: ARTI | AO5: ARTI | AP5: ARTI | AQ5: ARTI | AR5: ARTI | AS5: ARTI | AT5: ARTI | AU5: ARTI | AV5: ARTI | AW5: ARTI | AX5: ARTI | AY5: ARTI | AZ5: ARTI | BA5: ARTI | BB5: ARTI | BC5: ARTI | BD5: ARTI | BE5: ARTI | BF5: ARTI | BG5: ARTI | BH5: ARTI | BI5: ARTI | BJ5: ARTI | BK5: ARTI | BL5: ARTI | BM5: ARTI | BN5: ARTI | BO5: ARTI
B6: BASE OGL | C6: 40 | D6: Tract 2 | E6: =SUBTOTAL(9,E9:E205) -> 0 | F6: SURFACE | H6: =IF(H7=0,"","RECHECK") | I6: =IF(I7=0,"","RECHECK") | J6: =IF(J7=0,"","RECHECK") | K6: =IF(K7=0,"","RECHECK") | L6: =IF(L7=0,"","RECHECK") | M6: =IF(M7=0,"","RECHECK") | N6: =IF(N7=0,"","RECHECK") | O6: =IF(O7=0,"","RECHECK") | Q6: =IF(Q7=0,"","RECHECK") | R6: =IF(R7=0,"","RECHECK") | S6: =IF(S7=0,"","RECHECK") | T6: =IF(T7=0,"","RECHECK") | U6: =IF(U7=0,"","RECHECK") | V6: =IF(V7=0,"","RECHECK") | W6: =IF(W7=0,"","RECHECK") | X6: =IF(X7=0,"","RECHECK") | ... AA6: =IF(AA7=0,"","RECHECK") | AD6: =IF(AD7=0,"","RECHECK") | AE6: =IF(AE7=0,"","RECHECK") | AF6: =IF(AF7=0,"","RECHECK") | AG6: =IF(AG7=0,"","RECHECK") | AH6: =IF(AH7=0,"","RECHECK") | AI6: =IF(AI7=0,"","RECHECK") | AJ6: =IF(AJ7=0,"","RECHECK") | AK6: =IF(AK7=0,"","RECHECK") | ... GA6: =IF(GA7=0,"","RECHECK")
G7: =SUBTOTAL(9,G10:G206) -> 0 | H7: =SUBTOTAL(9,H10:H210) -> 0 | I7: =SUBTOTAL(9,I10:I210) -> 0 | J7: =SUBTOTAL(9,J10:J210) -> 0 | K7: =SUBTOTAL(9,K10:K210) -> 0 | L7: =SUBTOTAL(9,L10:L210) -> 0 | M7: =SUBTOTAL(9,M10:M206) -> 0 | N7: =SUBTOTAL(9,N10:N206) -> 0 | O7: =SUBTOTAL(9,O10:O206) -> 0 | P7: =SUBTOTAL(9,P10:P206) -> 0 | Q7: =SUBTOTAL(9,Q10:Q210) -> 0 | R7: =SUBTOTAL(9,R10:R206) -> 0 | S7: =SUBTOTAL(9,S10:S206) -> 0 | T7: =SUBTOTAL(9,T10:T206) -> 0 | U7: =SUBTOTAL(9,U10:U206) -> 0 | V7: =SUBTOTAL(9,V10:V206) -> 0 | W7: =SUBTOTAL(9,W10:W206) -> 0 | X7: =SUBTOTAL(9,X10:X206) -> 0 | Y7: =SUBTOTAL(9,Y10:Y206) -> 0 | Z7: 0 | AA7: =SUBTOTAL(9,AA10:AA210) -> 0 | AB7: =SUBTOTAL(9,AB10:AB207) -> 0 | AC7: =SUBTOTAL(9,AC10:AC201) -> 0 | AD7: =SUBTOTAL(9,AD10:AD201) -> 0 | AE7: =SUBTOTAL(9,AE10:AE201) -> 0 | AF7: =SUBTOTAL(9,AF10:AF201) -> 0 | AG7: =SUBTOTAL(9,AG10:AG206) -> 0 | AH7: =SUBTOTAL(9,AH10:AH202) -> 0 | AI7: =SUBTOTAL(9,AI10:AI206) -> 0 | AJ7: =SUBTOTAL(9,AJ10:AJ206) -> 0 | AK7: =SUBTOTAL(9,AK10:AK206) -> 0 | AL7: =SUBTOTAL(9,AL10:AL206) -> 0 | AM7: =SUBTOTAL(9,AM10:AM206) -> 0 | AN7: =SUBTOTAL(9,AN10:AN206) -> 0 | AO7: =SUBTOTAL(9,AO10:AO206) -> 0 | AP7: =SUBTOTAL(9,AP10:AP206) -> 0 | ... GA7: =SUBTOTAL(9,GA10:GA206) -> 0
A8: NOTES | C8: NET ACRES | D8: OWNERS | E8: TOTAL
C10: =IFERROR(IF($E10>0,$E10/SUMIF($E$10:$E$127,">0")*$D$5,""),"") | D10: United States of America | E10: =SUM(G10:HT10) -> -1 | H10: -1
C11: =IFERROR(IF($E11>0,$E11/SUMIF($E$10:$E$127,">0")*$D$5,""),"") | D11: Charles T. Kennett | E11: =SUM(G11:HT11) -> 0 | H11: 1 | I11: -1
C12: =IFERROR(IF($E12>0,$E12/SUMIF($E$10:$E$127,">0")*$D$5,""),"") -> 2.2222222 | D12: Barbara Bain | E12: =SUM(G12:HT12) -> 1 | I12: 1
C13: =IFERROR(IF($E13>0,$E13/SUMIF($E$10:$E$127,">0")*$D$5,""),"") | D13: Billy Wayne Bain | E13: =SUM(G13:HT13) -> -2 | J13: -1 | AO13: -1
C14: =IFERROR(IF($E14>0,$E14/SUMIF($E$10:$E$127,">0")*$D$5,""),"") | D14: Clarence C. Bain, Trustee | E14: =SUM(G14:HT14) -> 0 | J14: 1 | K14: -1 | L14: -1 | AC14: 1
C15: =IFERROR(IF($E15>0,$E15/SUMIF($E$10:$E$127,">0")*$D$5,""),"") -> 2.2222222 | D15: Dorothy J. Ba | E15: =SUM(G15:HT15) -> 1 | K15: 1
C16: =IFERROR(IF($E16>0,$E16/SUMIF($E$10:$E$127,">0")*$D$5,""),"") | D16: Alpine Oil and Royalty Co, Inc. | E16: =SUM(G16:HT16) -> 0 | J16: -1 | L16: 1
C17: =IFERROR(IF($E17>0,$E17/SUMIF($E$10:$E$127,">0")*$D$5,""),"") | D17: Melinda McCaul Mulvihill | E17: =SUM(G17:HT17) -> -1 | J17: 1 | P17: -1 | W17: -1
C18: =IFERROR(IF($E18>0,$E18/SUMIF($E$10:$E$127,">0")*$D$5,""),"") | D18: Wilson, Dwight J. Estate of | E18: =SUM(G18:HT18) -> -1 | K18: -1
C19: =IFERROR(IF($E19>0,$E19/SUMIF($E$10:$E$127,">0")*$D$5,""),"") -> 8.8888889 | D19: The Public | E19: =SUM(G19:HP19) -> 4 | K19: 1 | P19: 1 | AO19: 1 | BO19: 1
C20: =IFERROR(IF($E20>0,$E20/SUMIF($E$10:$E$127,">0")*$D$5,""),"") | D20: Jon T. Williams | E20: =SUM(G20:HP20) -> 0
C21: =IFERROR(IF($E21>0,$E21/SUMIF($E$10:$E$127,">0")*$D$5,""),"") | D21: Rogene E. Williams | E21: =SUM(G21:HT21) -> 0
C22: =IFERROR(IF($E22>0,$E22/SUMIF($E$10:$E$127,">0")*$D$5,""),"") | D22: Jon T. and Rogene E. Williams Trust | E22: =SUM(G22:HT22) -> 0
C23: =IFERROR(IF($E23>0,$E23/SUMIF($E$10:$E$127,">0")*$D$5,""),"") | D23: Jan A. Schroff | E23: =SUM(G23:HT23) -> 0
C24: =IFERROR(IF($E24>0,$E24/SUMIF($E$10:$E$127,">0")*$D$5,""),"") | D24: Jan A. Schroff, Trustee | E24: =SUM(G24:HT24) -> 0
C25: =IFERROR(IF($E25>0,$E25/SUMIF($E$10:$E$127,">0")*$D$5,""),"") | D25: David Slobin | E25: =SUM(G25:HT25) -> -2 | N25: -1 | O25: -1
C26: =IFERROR(IF($E26>0,$E26/SUMIF($E$10:$E$127,">0")*$D$5,""),"") -> 4.4444444 | D26: Myron Slobin | E26: =SUM(G26:HT26) -> 2 | N26: 1 | O26: 1
C27: =IFERROR(IF($E27>0,$E27/SUMIF($E$10:$E$127,">0")*$D$5,""),"") | D27: Eunice Evelyn Cook | E27: =SUM(G27:HT27) -> 0
C28: =IFERROR(IF($E28>0,$E28/SUMIF($E$10:$E$127,">0")*$D$5,""),"") | D28: Albert E. Fuchs | E28: =SUM(G28:HT28) -> 0
C29: =IFERROR(IF($E29>0,$E29/SUMIF($E$10:$E$127,">0")*$D$5,""),"") | D29: Aqu | E29: =SUM(G29:HT29) -> 0
C30: =IFERROR(IF($E30>0,$E30/SUMIF($E$10:$E$127,">0")*$D$5,""),"") | D30: Lola F. Richrads | E30: =SUM(G30:HT30) -> 0
C31: =IFERROR(IF($E31>0,$E31/SUMIF($E$10:$E$127,">0")*$D$5,""),"") | D31: Albert E. Fuchs, Trustee | E31: =SUM(G31:HT31) -> 0
C32: =IFERROR(IF($E32>0,$E32/SUMIF($E$10:$E$127,">0")*$D$5,""),"") | D32: Ocie H. Fuchs | E32: =SUM(G32:HT32) -> 0
C33: =IFERROR(IF($E33>0,$E33/SUMIF($E$10:$E$127,">0")*$D$5,""),"") | D33: Mark J. Fuchs | E33: =SUM(G33:HT33) -> 0
C34: =IFERROR(IF($E34>0,$E34/SUMIF($E$10:$E$127,">0")*$D$5,""),"") | D34: Jessie W. Fuchs | E34: =SUM(G34:HT34) -> 0
C35: =IFERROR(IF($E35>0,$E35/SUMIF($E$10:$E$127,">0")*$D$5,""),"") | D35: Raymond M. Fuchs | E35: =SUM(G35:HY35) -> 0
C36: =IFERROR(IF($E36>0,$E36/SUMIF($E$10:$E$127,">0")*$D$5,""),"") | D36: Isa May Smith | E36: =SUM(G36:HT36) -> 0
C37: =IFERROR(IF($E37>0,$E37/SUMIF($E$10:$E$127,">0")*$D$5,""),"") | D37: Melinda McCaul Mulvihill, Trustee | E37: =SUM(G37:HH37) -> 0
C38: =IFERROR(IF($E38>0,$E38/SUMIF($E$10:$E$127,">0")*$D$5,""),"") -> 2.2222222 | D38: Stephen M. Criser, Trustee | E38: =SUM(G38:HH38) -> 1 | W38: 1
C39: =IFERROR(IF($E39>0,$E39/SUMIF($E$10:$E$127,">0")*$D$5,""),"") | D39: William C. Bain Jr. | E39: =SUM(G39:HH39) -> 0
C40: =IFERROR(IF($E40>0,$E40/SUMIF($E$10:$E$127,">0")*$D$5,""),"") | D40: Donald R. Bain | E40: =SUM(G40:HH40) -> 0
C41: =IFERROR(IF($E41>0,$E41/SUMIF($E$10:$E$127,">0")*$D$5,""),"") | D41: Melvin F. Bain | E41: =SUM(G41:HH41) -> -1 | AK41: -1
...

Sheet Tract 3
E1: Instrument | H1: Patent | I1: Mineral Deed | J1: Mineral Deed | K1: Warranty Deed | L1: Mineral Deed | M1: Mineral Deed | N1: Mineral Deed | O1: Mineral Deed | P1: Decree | Q1: Mineral Deed | R1: Warranty Deed | S1: Final Decree | T1: Final Decree | U1: Mineral Deed | V1: Mineral Deed | W1: Mineral Deed | X1: Quit Claim Deed | Y1: Joint Tenancy Warranty Deed | Z1: Trustees Mineral Deed | AA1: Trustees Mineral Deed | AB1: Trustees Mineral Deed | AC1: Mineral Deed | AD1: Mineral Deed | AE1: Final Decree | AF1: Mineral Deed | AG1: Mineral Deed | AH1: Mineral Deed | AI1: Quit Claim Mineral Deed | AJ1: Mineral Deed
A2: 3 | B2: TRACT | D2: SE/4 NE/4, containing 40 acres | E2: Image Number | H2: 1909-002932 | I2: 1994-006415 | J2: 1995-003404 | K2: 1996-002352 | L2: 2000-007685 | M2: 2001-000957 | N2: 2001-001414 | O2: 2001-001463 | P2: 2001-002342 | Q2: 2002-004595 | R2: 2003-004945 | S2: 2003-005699 | T2: 2004-000099 | U2: 2004-005901 | V2: 2005-000158 | W2: 2005-007551 | X2: 2007-001848 | Y2: 2008-003157 | Z2: 2011-001007 | AA2: 2011-001008 | AB2: 2011-001009 | AC2: 2011-008134 | AD2: 2012-004060 | AE2: 2013-000518 | AF2: 2014-003089 | AG2: 2014-006293 | AI2: 2018-002650 | AJ2: 2021-001068
B3: DESCRIPTION | E3: Book / Page | H3: PAT006/7 | I3: 1422/0009 | J3: 1457/0173 | K3: 1510/0491 | L3: 1611/0503 | M3: 1637/0026 | N3: 1639/0206 | O3: 1639/0426 | P3: 1643/0389 | Q3: 1695/0238 | R3: 1724/0582 | S3: 1728/0457 | T3: 1734/0014 | U3: 1765/0306 | V3: 1774/0309 | W3: 1812/0138 | X3: 1872/0277 | Y3: 1914/0155 | Z3: 2063/0491 | AA3: 2063/0494 | AB3: 2063/0497 | AC3: 2106/0387 | AD3: 2141/0003 | AE3: 2177/0033 | AF3: 2251/0529 | AG3: 2273/0223 | AH3: 2376/0100 | AI3: 2406/0228 | AJ3: 2467/0476
E4: Date | H4: 3652 | I4: 34542 | J4: 34754 | K4: 35429 | L4: 36647 | M4: 36957 | N4: 36987 | O4: 36991 | P4: 37034 | Q4: 37592 | R4: 37897 | S4: 37937 | T4: 37994 | U4: 38281 | V4: 38365 | W4: 38658 | X4: 39197 | Y4: 39612 | Z4: 40592 | AA4: 40592 | AB4: 40592 | AC4: 40886 | AD4: 41061 | AE4: 41304 | AF4: 41774 | AG4: 41927 | AH4: 42996 | AI4: 43382 | AJ4: 44377
B5: TRACT ACRES | D5: 40 | E5: Conveyance | H5: ARTI | I5: ARTI | J5: ARTI | K5: ARTI | L5: ARTI | M5: ARTI | N5: ARTI | O5: ARTI | P5: ARTI | Q5: ARTI | R5: ARTI | S5: ARTI | T5: ARTI | U5: ARTI | V5: ARTI | W5: ARTI | X5: ARTI | Y5: ARTI | Z5: ARTI | AA5: ARTI | AB5: ARTI | AC5: ARTI | AD5: ARTI | AE5: ARTI | AF5: ARTI | AG5: ARTI | AH5: ARTI | AI5: ARTI | AJ5: ARTI
B6: BASE OGL | C6: 40 | D6: Tract 3 | E6: =SUBTOTAL(9,E9:E203) -> 0 | F6: SURFACE | H6: =IF(H7=0,"","RECHECK") | I6: =IF(I7=0,"","RECHECK") | J6: =IF(J7=0,"","RECHECK") | L6: =IF(L7=0,"","RECHECK") | M6: =IF(M7=0,"","RECHECK") | N6: =IF(N7=0,"","RECHECK") | O6: =IF(O7=0,"","RECHECK") | P6: =IF(P7=0,"","RECHECK") | Q6: =IF(Q7=0,"","RECHECK") | R6: =IF(R7=0,"","RECHECK") | S6: =IF(S7=0,"","RECHECK") | ... X6: =IF(X7=0,"","RECHECK") | AA6: =IF(AA7=0,"","RECHECK") | AB6: =IF(AB7=0,"","RECHECK") | AC6: =IF(AC7=0,"","RECHECK") | AD6: =IF(AD7=0,"","RECHECK") | AE6: =IF(AE7=0,"","RECHECK") | AF6: =IF(AF7=0,"","RECHECK") | AG6: =IF(AG7=0,"","RECHECK") | AH6: =IF(AH7=0,"","RECHECK") | ... FS6: =IF(FS7=0,"","RECHECK")
G7: =SUBTOTAL(9,G10:G204) -> 0 | H7: =SUBTOTAL(9,H10:H212) -> 0 | I7: =SUBTOTAL(9,I10:I212) -> 0 | J7: =SUBTOTAL(9,J10:J212) -> 0 | K7: =SUBTOTAL(9,K10:K208) -> 0 | L7: =SUBTOTAL(9,L10:L204) -> 0 | M7: =SUBTOTAL(9,M10:M204) -> 0 | N7: =SUBTOTAL(9,N10:N204) -> 0 | O7: =SUBTOTAL(9,O10:O204) -> 0 | P7: =SUBTOTAL(9,P10:P204) -> 0 | Q7: =SUBTOTAL(9,Q10:Q204) -> 0 | R7: =SUBTOTAL(9,R10:R204) -> 0 | S7: =SUBTOTAL(9,S10:S204) -> 0 | ... V7: =SUBTOTAL(9,V10:V204) -> 0 | W7: 0 | X7: =SUBTOTAL(9,X10:X208) -> 0 | Y7: =SUBTOTAL(9,Y10:Y212) -> 0 | Z7: =SUBTOTAL(9,Z10:Z206) -> 0 | AA7: =SUBTOTAL(9,AA10:AA206) -> 0 | AB7: =SUBTOTAL(9,AB10:AB206) -> 0 | AC7: =SUBTOTAL(9,AC10:AC206) -> 0 | AD7: =SUBTOTAL(9,AD10:AD204) -> 0 | AE7: =SUBTOTAL(9,AE10:AE203) -> 0 | AF7: =SUBTOTAL(9,AF10:AF204) -> 0 | AG7: =SUBTOTAL(9,AG10:AG206) -> 0 | AH7: =SUBTOTAL(9,AH10:AH204) -> 0 | AI7: =SUBTOTAL(9,AI10:AI204) -> 0 | AJ7: =SUBTOTAL(9,AJ10:AJ204) -> 0 | AK7: =SUBTOTAL(9,AK10:AK204) -> 0 | AL7: =SUBTOTAL(9,AL10:AL204) -> 0 | AM7: =SUBTOTAL(9,AM10:AM204) -> 0 | AN7: =SUBTOTAL(9,AN10:AN204) -> 0 | AO7: =SUBTOTAL(9,AO10:AO204) -> 0 | ... FS7: =SUBTOTAL(9,FS10:FS204) -> 0
A8: NOTES | C8: NET ACRES | D8: OWNERS | E8: TOTAL
C10: =IFERROR(IF($E10>0,$E10/SUMIF($E$10:$E$74,">0")*$D$5,""),"") | D10: United States of America | E10: =SUM(G10:HL10) -> -1 | H10: -1
C11: =IFERROR(IF($E11>0,$E11/SUMIF($E$10:$E$74,">0")*$D$5,""),"") -> 2.6666667 | D11: Ernest Brooks | E11: =SUM(G11:HL11) -> 1 | H11: 1
C12: =IFERROR(IF($E12>0,$E12/SUMIF($E$10:$E$74,">0")*$D$5,""),"") | D12: Hayhurst Oil Properties, Inc. | E12: =SUM(G12:HL12) -> -1 | I12: -1
C13: =IFERROR(IF($E13>0,$E13/SUMIF($E$10:$E$74,">0")*$D$5,""),"") -> 2.6666667 | D13: Nam Corporation | E13: =SUM(G13:HL13) -> 1 | I13: 1
C14: =IFERROR(IF($E14>0,$E14/SUMIF($E$10:$E$74,">0")*$D$5,""),"") | D14: Tripco, Inc. | E14: =SUM(G14:HL14) -> -2 | J14: -1 | W14: -1
C15: =IFERROR(IF($E15>0,$E15/SUMIF($E$10:$E$74,">0")*$D$5,""),"") -> 2.6666667 | D15: Prudential Securities | E15: =SUM(G15:HL15) -> 1 | J15: 1
C16: =IFERROR(IF($E16>0,$E16/SUMIF($E$10:$E$74,">0")*$D$5,""),"") | D16: Eula Cross | E16: =SUM(G16:HL16) -> 0
C17: =IFERROR(IF($E17>0,$E17/SUMIF($E$10:$E$74,">0")*$D$5,""),"") | D17: Floyd W. Atha | E17: =SUM(G17:HL17) -> 0
C18: =IFERROR(IF($E18>0,$E18/SUMIF($E$10:$E$74,">0")*$D$5,""),"") | D18: Nancy D. Atha | E18: =SUM(G18:HL18) -> 0
C19: =IFERROR(IF($E19>0,$E19/SUMIF($E$10:$E$74,">0")*$D$5,""),"") | D19: Fer-scher Exploration, LLC | E19: =SUM(G19:HL19) -> -1 | L19: -1
C20: =IFERROR(IF($E20>0,$E20/SUMIF($E$10:$E$74,">0")*$D$5,""),"") -> 2.6666667 | D20: Aspen Minerals Group | E20: =SUM(G20:HL20) -> 1 | L20: 1
C21: =IFERROR(IF($E21>0,$E21/SUMIF($E$10:$E$74,">0")*$D$5,""),"") | D21: Nanalee Faye Barnett | E21: =SUM(G21:HL21) -> -1 | M21: -1
C22: =IFERROR(IF($E22>0,$E22/SUMIF($E$10:$E$74,">0")*$D$5,""),"") -> 8 | D22: Arrowhead Resources, Inc. | E22: =SUM(G22:HL22) -> 3 | M22: 1 | N22: 1 | O22: 1
C23: =IFERROR(IF($E23>0,$E23/SUMIF($E$10:$E$74,">0")*$D$5,""),"") | D23: Louise Ormand | E23: =SUM(G23:HL23) -> -1 | N23: -1
C24: =IFERROR(IF($E24>0,$E24/SUMIF($E$10:$E$74,">0")*$D$5,""),"") | D24: Glenn D. Mitchel | E24: =SUM(G24:HL24) -> -1 | O24: -1
C25: =IFERROR(IF($E25>0,$E25/SUMIF($E$10:$E$74,">0")*$D$5,""),"") | D25: Jack E. Barnett, Deceased | E25: =SUM(G25:HL25) -> -1 | P25: -1
C26: =IFERROR(IF($E26>0,$E26/SUMIF($E$10:$E$74,">0")*$D$5,""),"") -> 8 | D26: The Public | E26: =SUM(G26:HL26) -> 3 | P26: 1 | S26: 1 | T26: 1
C27: =IFERROR(IF($E27>0,$E27/SUMIF($E$10:$E$74,">0")*$D$5,""),"") | D27: Hayhurst, Peggy J. Revoc Trust | E27: =SUM(G27:HL27) -> 0
C28: =IFERROR(IF($E28>0,$E28/SUMIF($E$10:$E$74,">0")*$D$5,""),"") | D28: Peggy J. | E28: =SUM(G28:HL28) -> 0
C29: =IFERROR(IF($E29>0,$E29/SUMIF($E$10:$E$74,">0")*$D$5,""),"") | D29: Bluebonnet Investments, Ltd. | E29: =SUM(G29:HL29) -> -1 | R29: -1
C30: =IFERROR(IF($E30>0,$E30/SUMIF($E$10:$E$74,">0")*$D$5,""),"") -> 2.6666667 | D30: White Birch, LP | E30: =SUM(G30:HL30) -> 1 | R30: 1
C31: =IFERROR(IF($E31>0,$E31/SUMIF($E$10:$E$74,">0")*$D$5,""),"") | D31: Glenn Douglas Mitchell, Deceased | E31: =SUM(G31:HL31) -> -1 | S31: -1
C32: =IFERROR(IF($E32>0,$E32/SUMIF($E$10:$E$74,">0")*$D$5,""),"") | D32: Evelyn Louise McLerran, Deceased | E32: =SUM(G32:HL32) -> -1 | T32: -1
C33: =IFERROR(IF($E33>0,$E33/SUMIF($E$10:$E$74,">0")*$D$5,""),"") | D33: Aspen Energy Group, Inc. | E33: =SUM(G33:HL33) -> -1 | U33: -1
C34: =IFERROR(IF($E34>0,$E34/SUMIF($E$10:$E$74,">0")*$D$5,""),"") -> 2.6666667 | D34: Crusader Energy Corporation | E34: =SUM(G34:HL34) -> 1 | U34: 1
C35: =IFERROR(IF($E35>0,$E35/SUMIF($E$10:$E$74,">0")*$D$5,""),"") | D35: Minion Investment Co | E35: =SUM(G35:HL35) -> 0
C36: =IFERROR(IF($E36>0,$E36/SUMIF($E$10:$E$74,">0")*$D$5,""),"") | D36: Brian L. Rice | E36: =SUM(G36:HL36) -> 0
C37: =IFERROR(IF($E37>0,$E37/SUMIF($E$10:$E$74,">0")*$D$5,""),"") -> 2.6666667 | D37: Prism Energy, Inc. | E37: =SUM(G37:HQ37) -> 1 | W37: 1
C38: =IFERROR(IF($E38>0,$E38/SUMIF($E$10:$E$74,">0")*$D$5,""),"") | D38: Atha Nancy D. | E38: =SUM(G38:HL38) -> 0
C39: =IFERROR(IF($E39>0,$E39/SUMIF($E$10:$E$74,">0")*$D$5,""),"") | D39: Atha Floyd Revoc Trust | E39: =SUM(G39:GZ39) -> 0
C40: =IFERROR(IF($E40>0,$E40/SUMIF($E$10:$E$74,">0")*$D$5,""),"") | D40: Floyd Atha, Trustee | E40: =SUM(G40:GZ40) -> 0
C41: =IFERROR(IF($E41>0,$E41/SUMIF($E$10:$E$74,">0")*$D$5,""),"") | D41: Floyd Co Atha, Trustee | E41: =SUM(G41:GZ41) -> 0
...

Sheet Tract 4
